Workbook

Sheet Sheet2
A1: Full Name | B1: New Grouping | C1: Session | D1: Weeks | E1: Phone Number
A2: Ainechi, Ariana | B2: K1G | C2: 2MD | D2: 6wks | E2: (516)528-9739
A3: Albert, Justin | B3: Exp B | C3: 3FD | D3: 4wks | E3: 516-551-7820
A4: Anderson, Victoria | B4: 4/5G | C4: 3FD | D4: 8wks | E4: (516)286-5998
A5: Andreani, Adison | B5: TeensG | C5: 5FD | D5: 7wks | E5: (516)458-5197
A6: Andreani, Ryan | B6: TeensB | C6: 5FD | D6: 7wks | E6: (516)458-5197
A7: Assortato, Chelsea | B7: 3G | C7: 3FD | D7: 7wks | E7: (516)779-0256
A8: Azan, Skylar | B8: Exp G | C8: 5FD | D8: 7wks | E8: (516)320-1664
A9: Baer, Ava | B9: a3's | C9: 5FD | D9: 8wks | E9: (516)497-6970
A10: Bailey, Dylan | B10: 4/5B | C10: 5FD | D10: 6wks | E10: (646)824-8413
A11: Bailey, Peyton | B11: K1G | C11: 5FD | D11: 6wks | E11: (646)824-8413
A12: Balalaos, Jason | B12: 2/3B | C12: 2FD | D12: 8wks | E12: (516)784-6152
... A47: Chase, Steven | B47: 4/5B | C47: 3FD | D47: 6wks | E47: (516)662-9258
A48: Chaves, Ava | B48: Exp G | C48: 5FD | E48: (516)642-6182
A49: Chaves, Emma | B49: Exp G | C49: 5FD | E49: (516)642-6182
A50: Cheung, Aidan | B50: TeensB | C50: 5FD | D50: 8wks | E50: (646)528-6521
A51: Cheung, Caleb | B51: 2/3B | C51: 5FD | D51: 8wks | E51: (646)528-6521
A52: Chiari, Mckenzie | B52: K1G | C52: 2FD | D52: 6wks | E52: (516)965-4546
A53: Christensen, Hannah | B53: a4's | C53: 2MD | D53: 6wks | E53: (516)776-1516
A54: Cinelli, Brayden | B54: TeensB | C54: 5FD | D54: 7wks
A55: Cinelli, Carter | B55: TeensB | C55: 5FD | D55: 7wks
A56: Cinelli, Kennedy | B56: 2G | C56: 4FD | D56: 7wks
A57: Cohen , Alexandra | B57: 3G | C57: 5FD | D57: 8wks | E57: (516)369-0762
A58: Cohen , Braden | B58: Exp B | C58: 4FD | D58: 6wks | E58: (516)972-4246
A59: Cohen , Matthew | B59: Exp B | C59: 5FD | D59: 8wks | E59: (516)369-0762
A60: Cullum, Joshua | B60: KB | C60: 3MD | D60: 8wks | E60: (516)316-5627
A61: Dall'aste, Jason | B61: TeensB | C61: 5FD | D61: 8wks | E61: (516)241-0700
A62: Dall'aste, Logan | B62: Exp B | C62: 5FD | D62: 8wks | E62: (516)241-0700
A63: D'Andrea, Frankie | B63: a4's | C63: 3FD | D63: 8wks | E63: (516)729-6740
A64: Daube, Makayla | B64: CIT | C64: 5FD | D64: 8wks | E64: (516)263-5796
A65: D'Auria, Anthony | B65: TeensB | C65: 5FD | D65: 6wks | E65: (646)964-7306
A66: DelGreco, Dominic | B66: a3's | C66: 3MD | D66: 8wks | E66: (516)287-0817
A67: Dishman, Hannah | B67: a4's | C67: 5FD | D67: 8wks | E67: (646)704-6444
A68: Dobladillo, Megan | B68: 2G | C68: 5FD | D68: 8wks | E68: (516)503-1860
... A76: Falabella, Kylie | B76: K1G | C76: 3FD | D76: 8wks | E76: (516)641-3969
A77: Falls, Sarah | B77: Exp G | C77: 5FD | E77: (516)784-1070
A78: Farber, Harrison | B78: 1B | C78: 3FD | D78: 6wks | E78: (516)238-8068
A79: Ferguson, Westley | B79: a4's | C79: 3MD | D79: 6wks | E79: (516)884-0746
A80: Ferreira, Luka | B80: a3's | C80: 2MD | D80: 4wks | E80: (516)216-2107
A81: Fielding, Eliza | B81: 3G | C81: 3FD | D81: 7wks | E81: (516)468-0057
...

Sheet Pivot Table 2
A2: =SUBSTITUTE(A3, "COUNTA of ", "") -> Group | B2: =SUBSTITUTE(B3, "COUNTA of ", "") -> # Students | C2: =SUBSTITUTE(C3, "SUM of ", "") | D2: =SUBSTITUTE(D3, "SUM of ", "")
A3: Group | B3: # Students
A4: Pk3 | B4: 9
A5: PK3.1 | B5: 14
A6: Pk4 | B6: 8
A7: Tod | B7: 13
A8: Grand Total | B8: 44

Sheet 2025
A1: Current Total | B1: =COUNTA(B5:B342) -> 52 | C1: Anything columns in Yellow should be filled out | D1: Anything in Green are Formulas, just copy and paste. DO NOT TYPE IN ANYTHING ELSE. PLEASE ASK DEVON IF ANY QUESTIONS.
AZ2: 9 | BA2: 32 | BB2: 16 | BC2: 25 | BD2: 26 | BE2: 2
A3: Color Legend | B3: BW Finished | C3: QB Finished | AA3: Preferences | AZ3: 2 | BA3: 3 | BB3: 4 | BC3: 5 | BD3: 6 | BE3: 7
A4: Enrolled Date | B4: First Name | C4: Last Name | D4: Full Name | E4: Birthday | F4: Shirt Size | G4: Age | H4: Group | I4: Session | J4: Weeks | K4: # of Days | L4: Start Date | M4: End Date | N4: In | O4: Out | P4: M | Q4: T | R4: W | S4: TH | T4: F | U4: Days | V4: Paper work? | W4: Referral? | X4: Diaper? | Y4: Services | Z4: Monetary Notes | AA4: Schedule Notes? | AB4: Emails | AC4: Phone | AD4: Health Notes | AE4: Medications | AF4: Allergy | AG4: Street | AH4: Town | AI4: State | AJ4: Zip | AK4: Full Address | AL4: Transportation? | AM4: RT # | AN4: Route Order | AO4: Temp RT | AP4: month | AQ4: year
A5: 45678 | B5: Veronica | C5: Gonzalez | D5: =CONCAT(Concat(C5, ", "), B5) -> Gonzalez, Veronica | E5: 44640 | G5: =(TODAY()-E5)/365 -> 3.8630137 | H5: PK3.1 | I5: 12 mon | K5: 5 | L5: 45901 | N5: 0.375 | O5: 0.14583333 | P5: M | Q5: T | R5: W | S5: TH | T5: F | U5: =P5&Q5&R5&S5&T5 -> MTWTHF | AB5: mikichimento@gmail.com | AC5: 516.603.3473 | AK5: =AG5&","&AH5&","&AI5&","&AJ5 -> ,,, | AP5: =MONTH(A5) -> 1 | AQ5: =YEAR(A5) -> 2025
A6: 45684 | B6: Kyle | C6: Ho | D6: =CONCAT(Concat(C6, ", "), B6) -> Ho, Kyle | E6: 45004 | G6: =(TODAY()-E6)/365 -> 2.8657534 | H6: PK3 | I6: 10 mon | J6: 8 | K6: 3 | L6: 45901 | N6: 0.375 | O6: 0.14583333 | R6: W | S6: TH | U6: =P6&Q6&R6&S6&T6 -> WTH | AA6: changed from 5 day to 3 4/12. Changed from 3 day to 2 6/23 dad was alumni | AB6: jonandjudy.ho@gmail.com, | AC6: 347.260.7835 | AK6: =AG6&","&AH6&","&AI6&","&AJ6 -> ,,, | AP6: =MONTH(A6) -> 1 | AQ6: =YEAR(A6) -> 2025
A7: 45693 | B7: Isaac | C7: Zhao | D7: =CONCAT(Concat(C7, ", "), B7) -> Zhao, Isaac | E7: 44767 | G7: =(TODAY()-E7)/365 -> 3.5150685 | H7: PK3.1 | I7: 10 mon | K7: 5 | L7: 45901 | N7: 0.375 | O7: 5 | P7: M | Q7: T | R7: W | S7: TH | T7: F | U7: =P7&Q7&R7&S7&T7 -> MTWTHF | Z7: cash payment | AB7: lydiawu418@gmail.com | AC7: 646.515.0866, 646-552-3151 | AF7: None | AG7: 18 fish ave. | AH7: Albertson | AI7: NY | AJ7: 11507 | AK7: =AG7&","&AH7&","&AI7&","&AJ7 -> 18 fish ave. ,Albertson ,NY,11507 | AP7: =MONTH(A7) -> 2 | AQ7: =YEAR(A7) -> 2025 | AZ7: 2 | BA7: 3 | BB7: 4 | BC7: 5 | BD7: 6 | BE7: 7
A8: 45718 | B8: ayan | C8: shah | D8: =CONCAT(Concat(C8, ", "), B8) -> shah, ayan | E8: 45058 | G8: =(TODAY()-E8)/365 -> 2.7178082 | H8: PK3 | I8: 10mon | K8: 5 | L8: 45901 | N8: 0.375 | O8: 12 | P8: M | Q8: T | R8: W | S8: TH | T8: F | U8: =P8&Q8&R8&S8&T8 -> MTWTHF | AA8: sibling of current student | AB8: 516.669.2969 | AP8: =MONTH(A8) -> 3 | AQ8: =YEAR(A8) -> 2025
A9: 45721 | B9: finnula | C9: o connell | D9: =CONCAT(Concat(C9, ", "), B9) -> o connell, finnula | E9: 45138 | G9: =(TODAY()-E9)/365 -> 2.4986301 | H9: PK3 | I9: 10 mon | J9: 4 | K9: 5 | L9: 45901 | N9: 0.375 | O9: 12 | P9: M | Q9: T | R9: W | S9: TH | T9: F | U9: =P9&Q9&R9&S9&T9 -> MTWTHF | AA9: would like to be in the room with higherend of the agre group | AB9: kmsmith548@gmail.com, soconnell354@gmail.com | AC9: 516.242.9738 , 845-538-5275 | AF9: None | AG9: 29 Croyden rd. | AH9: Mineola | AI9: NY | AJ9: 11501 | AP9: =MONTH(A9) -> 3 | AQ9: =YEAR(A9) -> 2025
A10: 45743 | B10: sequoia | C10: leung | D10: =CONCAT(Concat(C10, ", "), B10) -> leung, sequoia | E10: 45023 | G10: =(TODAY()-E10)/365 -> 2.8136986 | H10: PK3 | I10: 12 mon | K10: 5 | L10: 45838 | M10: 46265 | N10: 0.35416667 | O10: 0.22916667 | P10: M | Q10: T | R10: W | S10: TH | T10: F | U10: =P10&Q10&R10&S10&T10 -> MTWTHF | AA10: 1hr extension | AB10: anga0501@gmail.com, patrickl.mail@gmail.com | AC10: 630.202.5156 | AP10: =MONTH(A10) -> 3 | AQ10: =YEAR(A10) -> 2025
A11: 45782 | B11: Dylan | C11: Salazar | D11: =CONCAT(Concat(C11, ", "), B11) -> Salazar, Dylan | E11: 44565 | G11: =(TODAY()-E11)/365 -> 4.0684932 | H11: PK3.1 | I11: 10 mon | K11: 5 | L11: 45901 | N11: 0.375 | O11: 0.52083333 | P11: M | Q11: T | R11: W | S11: TH | T11: FR | U11: =P11&Q11&R11&S11&T11 -> MTWTHFR | AB11: didonnellan@yahoo.com, | AC11: 917.225.0914 | AP11: =MONTH(A11) -> 5 | AQ11: =YEAR(A11) -> 2025
A12: 45782 | B12: Alex | C12: Salazar | D12: =CONCAT(Concat(C12, ", "), B12) -> Salazar, Alex | E12: 44565 | G12: =(TODAY()-E12)/365 -> 4.0684932 | H12: PK3.1 | I12: 10 mon | K12: 5 | L12: 45901 | N12: 0.375 | O12: 0.52083333 | P12: M | Q12: T | R12: w | S12: TH | T12: FR | U12: =P12&Q12&R12&S12&T12 -> MTwTHFR | AB12: didonnellan@yahoo.com, | AC12: 917.225.0914 | AP12: =MONTH(A12) -> 5 | AQ12: =YEAR(A12) -> 2025
A13: 45782 | B13: Wesley | C13: Lung | D13: =CONCAT(Concat(C13, ", "), B13) -> Lung, Wesley | E13: 45216 | G13: =(TODAY()-E13)/365 -> 2.2849315 | H13: TOD | I13: 12 mon | K13: 5 | L13: 45838 | M13: 46202 | N13: 0.375 | O13: 5 | P13: M | Q13: T | R13: W | S13: TH | T13: F | U13: =P13&Q13&R13&S13&T13 -> MTWTHF | AB13: ceciliatow@gmail.com, jonathan.lung@gmail.com | AC13: 917.836.2889 | AD13: NO ALLERGIES | AP13: =MONTH(A13) -> 5 | AQ13: =YEAR(A13) -> 2025
A14: 45783 | B14: Nancy | C14: Cesta | D14: =CONCAT(Concat(C14, ", "), B14) -> Cesta, Nancy | E14: 44607 | G14: =(TODAY()-E14)/365 -> 3.9534247 | H14: PK3.1 | I14: 10 mon | K14: 5 | L14: 45901 | N14: 9 | O14: 5 | P14: M | Q14: T | R14: W | S14: TH | T14: F | U14: =P14&Q14&R14&S14&T14 -> MTWTHF | AC14: 646.773.5399 | AP14: =MONTH(A14) -> 5 | AQ14: =YEAR(A14) -> 2025
A15: 45783 | B15: Rebecca | C15: Abraham | D15: =CONCAT(Concat(C15, ", "), B15) -> Abraham, Rebecca | E15: 44559 | G15: =(TODAY()-E15)/365 -> 4.0849315 | H15: PK4 | I15: 10 mon | K15: 3 | L15: 45901 | N15: 0.375 | O15: 0.14583333 | P15: M | Q15: T | S15: TH | U15: =P15&Q15&R15&S15&T15 -> MTTH | Z15: paid | AB15: rabraham.ny@gmail.com, nishaverghese@gmail.com | AC15: 516-673-8579, 718-404-4366 | AD15: Peanut Allergy | AF15: Peanut | AG15: 50 Browers Ln. | AI15: NY | AP15: =MONTH(A15) -> 5 | AQ15: =YEAR(A15) -> 2025
A16: 45804 | B16: Greyson | C16: Kerney | D16: =CONCAT(Concat(C16, ", "), B16) -> Kerney, Greyson | E16: 44909 | G16: =(TODAY()-E16)/365 -> 3.1260274 | H16: PK3.1 | I16: 10m | K16: 5 | L16: 45901 | N16: 0.375 | O16: 12 | P16: M | Q16: T | R16: W | S16: TH | T16: F | U16: =P16&Q16&R16&S16&T16 -> MTWTHF | Y16: Earky intervention/special education | AA16: prefer Ms Lisa due to familiarity | AB16: stacy.kerney@icloud.com, tkerney16@gmail.com | AC16: 516-317-8022 , 516-996-6564 | AP16: =MONTH(A16) -> 5 | AQ16: =YEAR(A16) -> 2025
A17: 45805 | B17: Amelia | C17: Kim | D17: =CONCAT(Concat(C17, ", "), B17) -> Kim, Amelia | E17: 45191 | G17: =(TODAY()-E17)/365 -> 2.3534247 | H17: TOD | I17: 10 mon | K17: 3 | L17: 45901 | N17: 9 | O17: 0.52083333 | P17: M | R17: W | T17: F | U17: =P17&Q17&R17&S17&T17 -> MWF | AP17: =MONTH(A17) -> 5 | AQ17: =YEAR(A17) -> 2025
A18: 45813 | B18: Grace | C18: Devadas | D18: =CONCAT(Concat(C18, ", "), B18) -> Devadas, Grace | E18: 45187 | G18: =(TODAY()-E18)/365 -> 2.3643836 | H18: TOD | I18: 10 mon | K18: 3 | L18: 45901 | N18: 0.375 | O18: 12 | R18: W | S18: TH | T18: F | U18: =P18&Q18&R18&S18&T18 -> WTHF | W18: Raquel Kim | AB18: sunny.cho06@gmail.com, Jdevadas2005@yahoo.com | AC18: 917-683-4189 , 718-581-8219 | AF18: Egg allergy | AG18: 40 Knolls Dr. | AH18: New hyde Park | AI18: NY | AJ18: 11040 | AP18: =MONTH(A18) -> 6 | AQ18: =YEAR(A18) -> 2025
A19: 45818 | B19: Lyanna | C19: Huallparimachi | D19: =CONCAT(Concat(C19, ", "), B19) -> Huallparimachi, Lyanna | G19: =(TODAY()-E19)/365 -> 126.16438 | H19: Infant | U19: =P19&Q19&R19&S19&T19 | Z19: put deposi down | AB19: Raulhc_@hotmail.com | AC19: 516 669 4238 | AP19: =MONTH(A19) -> 6 | AQ19: =YEAR(A19) -> 2025
A20: 45829 | B20: Ariana | C20: Kushinsky N. | D20: =CONCAT(Concat(C20, ", "), B20) -> Kushinsky N. , Ariana | E20: 44767 | G20: =(TODAY()-E20)/365 -> 3.5150685 | H20: PK3.1 | I20: 10 mon | K20: 2 | L20: 45901 | N20: 9 | O20: 0.5 | P20: M | Q20: T | U20: =P20&Q20&R20&S20&T20 -> MT | W20: Evie | Y20: pending | AA20: deposit paid | AB20: kcanales2@northwell.edu, shaunkush525@gmail.com | AC20: 516-474-0048, 516-745-6521 | AF20: None | AG20: 190 mieola blvd | AH20: Mineola | AI20: NY | AP20: =MONTH(A20) -> 6 | AQ20: =YEAR(A20) -> 2025
A21: 45849 | B21: Jack | C21: Torres | D21: =CONCAT(Concat(C21, ", "), B21) -> Torres, Jack | E21: 45592 | G21: =(TODAY()-E21)/365 -> 1.2547945 | H21: Infant | I21: 10m | K21: 5 | L21: 45944 | N21: M,T 8:30 | 7:15 | O21: M,T 4:30 | 3:15 | P21: M | Q21: T | R21: W | S21: TH | T21: F | U21: =P21&Q21&R21&S21&T21 -> MTWTHF | Z21: put deposit down | AA21: just for october, tuesday and thursdays 7:15-3:15 | AB21: jtorres1527@gmail.com | AC21: 787-378-6060 , 917-325-8170 | AP21: =MONTH(A21) -> 7 | AQ21: =YEAR(A21) -> 2025
A22: 45905 | B22: Amelia | C22: Vonbuttgerett | D22: =CONCAT(Concat(C22, ", "), B22) -> Vonbuttgerett, Amelia | E22: 45624 | G22: =(TODAY()-E22)/365 -> 1.1671233 | H22: Infant | I22: 10 mon | K22: 3 | L22: 45944 | N22: 9 | O22: 0.14583333 | P22: M | R22: W | S22: TH | U22: =P22&Q22&R22&S22&T22 -> MWTH | Z22: deposit paid | AB22: mary5885@optonline.net | AC22: 5162443969 | AP22: =MONTH(A22) -> 9 | AQ22: =YEAR(A22) -> 2025
A23: 45905 | B23: Leo | C23: Lajer | D23: =CONCAT(Concat(C23, ", "), B23) -> Lajer, Leo | H23: Infant | U23: =P23&Q23&R23&S23&T23 | Z23: deposit paid | AA23: not going ahead with RR | AB23: simkoi96@gmail.com | AP23: =MONTH(A23) -> 9 | AQ23: =YEAR(A23) -> 2025
A24: 45905 | B24: alex | C24: blanco | D24: =CONCAT(Concat(C24, ", "), B24) -> blanco, alex | G24: =(TODAY()-E24)/365 -> 126.16438 | H24: infant | U24: =P24&Q24&R24&S24&T24 | Z24: put deposit | AA24: decided to go with another program | AB24: lizruiz68@gmail.com | AP24: =MONTH(A24) -> 9 | AQ24: =YEAR(A24) -> 2025
A25: 45908 | B25: Diya | C25: Bhattacharya | D25: =CONCAT(Concat(C25, ", "), B25) -> Bhattacharya, Diya | G25: =(TODAY()-E25)/365 -> 126.16438 | H25: PK3 | I25: 10 mon | K25: 2 | L25: 45901 | N25: 9 | O25: 12 | P25: M | R25: W | U25: =P25&Q25&R25&S25&T25 -> MW | V25: Done | AP25: =MONTH(A25) -> 9 | AQ25: =YEAR(A25) -> 2025
A26: 45918 | B26: christopher | C26: cusumano | D26: =CONCAT(Concat(C26, ", "), B26) -> cusumano , christopher | E26: 45613 | G26: =(TODAY()-E26)/365 -> 1.1972603 | H26: infant | I26: 10 mon | K26: 5 | N26: 9 | O26: 12 | P26: m | Q26: t | R26: w | S26: th | T26: f | U26: =P26&Q26&R26&S26&T26 -> mtwthf | AC26: 718 502-4777 | AP26: =MONTH(A26) -> 9 | AQ26: =YEAR(A26) -> 2025
A27: 45919 | B27: sarah | C27: uddin | D27: =CONCAT(Concat(C27, ", "), B27) -> uddin, sarah | E27: 45890 | G27: =(TODAY()-E27)/365 -> 0.43835616 | H27: infant | K27: 3 | L27: 46143 | N27: 9 | O27: 0.70833333 | P27: M | Q27: T (9-1) | S27: TH (9-1) | U27: =P27&Q27&R27&S27&T27 -> MT (9-1)TH (9-1) | Z27: put down deposit | AA27: Wants 1 8 hr and 2 4hrs so total of 2 8hrs a week | AB27: tasniah@gmail.com | AC27: 7187305733 | AP27: =MONTH(A27) -> 9 | AQ27: =YEAR(A27) -> 2025
A28: 45919 | B28: vedant | C28: singh | D28: =CONCAT(Concat(C28, ", "), B28) -> singh, vedant | E28: 45634 | G28: =(TODAY()-E28)/365 -> 1.139726 | H28: infant | I28: 12 mon | K28: 5 | L28: 45944 | N28: 0.39583333 | O28: 0.22916667 | U28: =P28&Q28&R28&S28&T28 | Z28: deposit paid | AB28: jonaki.singh23@gmail.com | AC28: 7184149222 | AP28: =MONTH(A28) -> 9 | AQ28: =YEAR(A28) -> 2025
A29: 45924 | B29: remy | C29: le-gall | D29: =CONCAT(Concat(C29, ", "), B29) -> le-gall, remy | G29: 1.4 | H29: infant | I29: 12 mon | K29: 3 | L29: 45944 | N29: 9 | O29: 12 | P29: M | Q29: T | R29: W | U29: =P29&Q29&R29&S29&T29 -> MTW | Z29: deposit paid | AB29: xaglegall@gmail.com | AC29: 5187790753 | AP29: =MONTH(A29) -> 9 | AQ29: =YEAR(A29) -> 2025
B30: tyler | C30: wong | D30: =CONCAT(Concat(C30, ", "), B30) -> wong, tyler | G30: =(TODAY()-E30)/365 -> 126.16438 | H30: toddler | U30: =P30&Q30&R30&S30&T30 | Z30: put deposit | AA30: fall 2026 | AP30: =MONTH(A30) -> 12 | AQ30: =YEAR(A30) -> 1899
B31: Logan | C31: Tuomey | D31: =CONCAT(Concat(C31, ", "), B31) -> Tuomey, Logan | E31: 44963 | G31: =(TODAY()-E31)/365 -> 2.9780822 | H31: pk3.1 | I31: 10 mon | K31: 2 | L31: 45931 | N31: 9 | O31: 12 | P31: M | R31: W | U31: =P31&Q31&R31&S31&T31 -> MW | AP31: =MONTH(A31) -> 12 | AQ31: =YEAR(A31) -> 1899
B32: Mason | C32: Sudek | D32: =CONCAT(Concat(C32, ", "), B32) -> Sudek, Mason | G32: =(TODAY()-E32)/365 -> 126.16438 | U32: =P32&Q32&R32&S32&T32 | Z32: put down deposit | AP32: =MONTH(A32) -> 12 | AQ32: =YEAR(A32) -> 1899
B33: Allison | C33: Sookdeo | D33: =CONCAT(Concat(C33, ", "), B33) -> Sookdeo, Allison | G33: =(TODAY()-E33)/365 -> 126.16438 | H33: TOD | I33: 10 mon | K33: 5 | L33: 45901 | N33: 7 (M,W) 9 (TTHF) | O33: 3:30 (MW) 12 (TTHF) | P33: M | Q33: T | R33: W | S33: TH | T33: F | U33: =P33&Q33&R33&S33&T33 -> MTWTHF | AP33: =MONTH(A33) -> 12 | AQ33: =YEAR(A33) -> 1899
B34: Charli | C34: Saunders | D34: =CONCAT(Concat(C34, ", "), B34) -> Saunders, Charli | G34: 2 | H34: TOD | I34: 10 mon | K34: 2 | L34: 45901 | N34: 9 | O34: 12 | Q34: T | R34: W | U34: =P34&Q34&R34&S34&T34 -> TW | V34: put down deposit | Z34: put down deposit | AB34: k.merlo77@yahoo.com | AP34: =MONTH(A34) -> 12 | AQ34: =YEAR(A34) -> 1899
B35: Theodore | C35: Satalino | D35: =CONCAT(Concat(C35, ", "), B35) -> Satalino, Theodore | E35: 44912 | G35: =(TODAY()-E35)/365 -> 3.1178082 | H35: PK3.1 | I35: 10 mon | K35: 2 | L35: 45944 | N35: 0.3125 | O35: 0.14583333 | P35: M | R35: W | U35: =P35&Q35&R35&S35&T35 -> MW | Z35: put down deposit | AB35: smcapito@gmail.com | AP35: =MONTH(A35) -> 12 | AQ35: =YEAR(A35) -> 1899
B36: Luca | C36: Satalino | D36: =CONCAT(Concat(C36, ", "), B36) -> Satalino, Luca | E36: 45487 | G36: =(TODAY()-E36)/365 -> 1.5424658 | H36: Infant | I36: 10 mon | K36: 2 | L36: 45944 | N36: 0.29166667 | O36: 0.125 | P36: M | R36: W | U36: =P36&Q36&R36&S36&T36 -> MW | Z36: put down deposit | AC36: 5162876647 | AP36: =MONTH(A36) -> 12 | AQ36: =YEAR(A36) -> 1899
B37: Daniel | C37: Roland | D37: =CONCAT(Concat(C37, ", "), B37) -> Roland, Daniel | E37: 45310 | G37: =(TODAY()-E37)/365 -> 2.0273973 | H37: TOD | I37: 10 mon | K37: 5 | L37: 45901 | N37: 9 | O37: 5 | P37: M | Q37: T | R37: W | S37: TH | T37: F | U37: =P37&Q37&R37&S37&T37 -> MTWTHF | V37: i need papework | Z37: Paid deposit | AB37: chelsey.martino11@yahoo.com, danieljroland@hotmail.com | AP37: =MONTH(A37) -> 12 | AQ37: =YEAR(A37) -> 1899
B38: evelyn | C38: pollakusky | D38: =CONCAT(Concat(C38, ", "), B38) -> pollakusky , evelyn | E38: 44945 | G38: =(TODAY()-E38)/365 -> 3.0273973 | H38: PK3 | I38: 10 mon | K38: 3 | L38: 45901 | N38: 9 | O38: 12 | P38: M | Q38: T | S38: TH | U38: =P38&Q38&R38&S38&T38 -> MTTH | V38: enrollment contract? | AB38: christine.m.cusumano@gmail.com | AP38: =MONTH(A38) -> 12 | AQ38: =YEAR(A38) -> 1899
B39: Francis | C39: Peluso | D39: =CONCAT(Concat(C39, ", "), B39) -> Peluso, Francis | E39: 45114 | G39: =(TODAY()-E39)/365 -> 2.5643836 | H39: TOD | I39: 12 mon | K39: 3 | L39: 45901 | N39: 0.35416667 | O39: 5 | P39: M | Q39: T | R39: W | U39: =P39&Q39&R39&S39&T39 -> MTW | Z39: put deposit down | AB39: dpkrpc@gmail.com | AC39: 5082830552 , 3475253582 | AP39: =MONTH(A39) -> 12 | AQ39: =YEAR(A39) -> 1899
B40: Diana | C40: Murca | D40: =CONCAT(Concat(C40, ", "), B40) -> Murca , Diana | G40: =(TODAY()-E40)/365 -> 126.16438 | H40: PK4 | I40: 10 mon | K40: 3 | L40: 45901 | N40: 9 | O40: 0.14583333 | P40: M | R40: W | T40: F | U40: =P40&Q40&R40&S40&T40 -> MWF | AP40: =MONTH(A40) -> 12 | AQ40: =YEAR(A40) -> 1899
...

Sheet Daily Student Counts
B3: Group | C3: Mon | D3: Tue | E3: Weds | F3: Thur | G3: Fri
B4: Infant | C4: 5 | D4: 3 | E4: 5 | F4: 3 | G4: 2
B5: PK3 | C5: 5 | D5: 4 | E5: 5 | F5: 5 | G5: 3
B6: PK3.1 | C6: 9 | D6: 7 | E6: 8 | F6: 6 | G6: 6
B7: PK4 | C7: 3 | D7: 2 | E7: 1 | F7: 2 | G7: 1
B8: TOD | C8: 8 | D8: 7 | E8: 10 | F8: 6 | G8: 7
B9: Grand Total | C9: 30 | D9: 23 | E9: 29 | F9: 22 | G9: 19

Sheet Daily Count by Group
C1: Daily Count by Group
A2: GROUP | B2: # Students | C2: Week 1 | H2: Week 2 | M2: Week 3 | R2: Week 4 | W2: Week 5 | AB2: Week 6 | AG2: Week 7 | AL2: Week 8
C3: =SUBSTITUTE(C4, "SUM of ", "") -> 6/30 | D3: =SUBSTITUTE(D4, "SUM of ", "") -> 7/1 | E3: =SUBSTITUTE(E4, "SUM of ", "") -> 7/2 | F3: =SUBSTITUTE(F4, "SUM of ", "") -> 7/3 | G3: =SUBSTITUTE(G4, "SUM of ", "") -> 7/4 | H3: =SUBSTITUTE(H4, "SUM of ", "") -> 7/7 | I3: =SUBSTITUTE(I4, "SUM of ", "") -> 7/8 | J3: =SUBSTITUTE(J4, "SUM of ", "") -> 7/9 | ... AP3: =SUBSTITUTE(AP4, "SUM of ", "") -> 8/22
A4: Group | B4: COUNTUNIQUE of Full Name | C4: SUM of 6/30 | D4: SUM of 7/1 | E4: SUM of 7/2 | F4: SUM of 7/3 | G4: SUM of 7/4 | H4: SUM of 7/7 | I4: SUM of 7/8 | J4: SUM of 7/9 | K4: SUM of 7/10 | L4: SUM of 7/11 | M4: SUM of 7/14 | N4: SUM of 7/15 | O4: SUM of 7/16 | P4: SUM of 7/17 | Q4: SUM of 7/18 | R4: SUM of 7/21 | S4: SUM of 7/22 | T4: SUM of 7/23 | U4: SUM of 7/24 | V4: SUM of 7/25 | W4: SUM of 7/28 | X4: SUM of 7/29 | Y4: SUM of 7/30 | Z4: SUM of 7/31 | AA4: SUM of 8/1 | AB4: SUM of 8/4 | AC4: SUM of 8/5 | AD4: SUM of 8/6 | AE4: SUM of 8/7 | AF4: SUM of 8/8 | AG4: SUM of 8/11 | AH4: SUM of 8/12 | AI4: SUM of 8/13 | AJ4: SUM of 8/14 | AK4: SUM of 8/15 | AL4: SUM of 8/18 | AM4: SUM of 8/19 | AN4: SUM of 8/20 | AO4: SUM of 8/21 | AP4: SUM of 8/22
A5: 1B | B5: 4 | C5: 1 | D5: 0 | E5: 1 | F5: 0 | G5: 0 | H5: 3 | I5: 2 | J5: 3 | K5: 2 | L5: 3 | M5: 3 | N5: 2 | O5: 3 | P5: 2 | Q5: 3 | R5: 3 | S5: 2 | T5: 3 | U5: 2 | V5: 3 | W5: 3 | X5: 2 | Y5: 3 | Z5: 2 | AA5: 3 | AB5: 3 | AC5: 2 | AD5: 3 | AE5: 2 | AF5: 3 | AG5: 3 | AH5: 2 | AI5: 3 | AJ5: 2 | AK5: 3 | AL5: 2 | AM5: 1 | AN5: 2 | AO5: 1 | AP5: 2
A6: 1G | B6: 9 | C6: 2 | D6: 3 | E6: 3 | F6: 2 | G6: 0 | H6: 2 | I6: 8 | J6: 7 | K6: 7 | L6: 1 | M6: 2 | N6: 8 | O6: 7 | P6: 7 | Q6: 1 | R6: 3 | S6: 9 | T6: 8 | U6: 8 | V6: 2 | W6: 3 | X6: 9 | Y6: 8 | Z6: 8 | AA6: 2 | AB6: 3 | AC6: 8 | AD6: 7 | AE6: 7 | AF6: 2 | AG6: 2 | AH6: 7 | AI6: 6 | AJ6: 7 | AK6: 2 | AL6: 2 | AM6: 5 | AN6: 5 | AO6: 5 | AP6: 2
A7: 2B | B7: 8 | C7: 4 | D7: 5 | E7: 5 | F7: 5 | G7: 0 | H7: 6 | I7: 6 | J7: 6 | K7: 6 | L7: 5 | M7: 6 | N7: 6 | O7: 6 | P7: 6 | Q7: 5 | R7: 6 | S7: 6 | T7: 6 | U7: 6 | V7: 5 | W7: 6 | X7: 7 | Y7: 7 | Z7: 7 | AA7: 5 | AB7: 6 | AC7: 7 | AD7: 7 | AE7: 7 | AF7: 5 | AG7: 5 | AH7: 6 | AI7: 6 | AJ7: 6 | AK7: 4 | AL7: 4 | AM7: 5 | AN7: 5 | AO7: 5 | AP7: 3
A8: 2G | B8: 8 | C8: 4 | D8: 2 | E8: 4 | F8: 2 | G8: 0 | H8: 7 | I8: 3 | J8: 7 | K8: 3 | L8: 7 | M8: 8 | N8: 4 | O8: 8 | P8: 4 | Q8: 8 | R8: 8 | S8: 4 | T8: 8 | U8: 4 | V8: 8 | W8: 8 | X8: 4 | Y8: 8 | Z8: 4 | AA8: 8 | AB8: 6 | AC8: 4 | AD8: 6 | AE8: 4 | AF8: 6 | AG8: 6 | AH8: 4 | AI8: 6 | AJ8: 4 | AK8: 6 | AL8: 5 | AM8: 3 | AN8: 5 | AO8: 3 | AP8: 5
A9: 3B | B9: 6 | C9: 1 | D9: 1 | E9: 1 | F9: 1 | G9: 0 | H9: 2 | I9: 2 | J9: 2 | K9: 2 | L9: 2 | M9: 3 | N9: 2 | O9: 3 | P9: 2 | Q9: 3 | R9: 3 | S9: 2 | T9: 3 | U9: 2 | V9: 3 | W9: 3 | X9: 2 | Y9: 3 | Z9: 2 | AA9: 3 | AB9: 3 | AC9: 2 | AD9: 3 | AE9: 2 | AF9: 3 | AG9: 3 | AH9: 2 | AI9: 3 | AJ9: 2 | AK9: 3 | AL9: 3 | AM9: 2 | AN9: 3 | AO9: 2 | AP9: 3
A10: 3G | B10: 6 | C10: 4 | D10: 3 | E10: 4 | F10: 3 | G10: 0 | H10: 4 | I10: 4 | J10: 5 | K10: 4 | L10: 4 | M10: 4 | N10: 4 | O10: 5 | P10: 4 | Q10: 4 | R10: 5 | S10: 5 | T10: 6 | U10: 5 | V10: 5 | W10: 5 | X10: 5 | Y10: 6 | Z10: 5 | AA10: 5 | AB10: 5 | AC10: 5 | AD10: 6 | AE10: 5 | AF10: 5 | AG10: 5 | AH10: 5 | AI10: 6 | AJ10: 5 | AK10: 5 | AL10: 5 | AM10: 5 | AN10: 6 | AO10: 5 | AP10: 5
A11: 4B | B11: 6 | C11: 5 | D11: 5 | E11: 5 | F11: 5 | G11: 0 | H11: 5 | I11: 5 | J11: 5 | K11: 5 | L11: 4 | M11: 5 | N11: 5 | O11: 5 | P11: 5 | Q11: 4 | R11: 5 | S11: 5 | T11: 5 | U11: 5 | V11: 4 | W11: 5 | X11: 5 | Y11: 5 | Z11: 5 | AA11: 4 | AB11: 4 | AC11: 4 | AD11: 4 | AE11: 4 | AF11: 3 | AG11: 4 | AH11: 4 | AI11: 4 | AJ11: 4 | AK11: 3 | AL11: 4 | AM11: 4 | AN11: 4 | AO11: 4 | AP11: 3
A12: 4G | B12: 5 | C12: 1 | D12: 1 | E12: 2 | F12: 2 | G12: 0 | H12: 2 | I12: 2 | J12: 2 | K12: 2 | L12: 2 | M12: 2 | N12: 2 | O12: 2 | P12: 2 | Q12: 2 | R12: 2 | S12: 2 | T12: 2 | U12: 2 | V12: 2 | W12: 2 | X12: 2 | Y12: 2 | Z12: 2 | AA12: 2 | AB12: 2 | AC12: 2 | AD12: 2 | AE12: 2 | AF12: 2 | AG12: 2 | AH12: 2 | AI12: 2 | AJ12: 2 | AK12: 2 | AL12: 1 | AM12: 1 | AN12: 1 | AO12: 1 | AP12: 1
A13: 5G | B13: 1 | C13: 0 | D13: 0 | E13: 0 | F13: 0 | G13: 0 | H13: 0 | I13: 0 | J13: 0 | K13: 0 | L13: 0 | M13: 1 | N13: 0 | O13: 1 | P13: 0 | Q13: 1 | R13: 1 | S13: 0 | T13: 1 | U13: 0 | V13: 1 | W13: 1 | X13: 0 | Y13: 1 | Z13: 0 | AA13: 1 | AB13: 1 | AC13: 0 | AD13: 1 | AE13: 0 | AF13: 1 | AG13: 1 | AH13: 0 | AI13: 1 | AJ13: 0 | AK13: 1 | AL13: 1 | AM13: 0 | AN13: 1 | AO13: 0 | AP13: 1
A14: CIT | B14: 2 | C14: 2 | D14: 2 | E14: 2 | F14: 2 | G14: 0 | H14: 2 | I14: 2 | J14: 2 | K14: 2 | L14: 2 | M14: 2 | N14: 2 | O14: 2 | P14: 2 | Q14: 2 | R14: 2 | S14: 2 | T14: 2 | U14: 2 | V14: 2 | W14: 2 | X14: 2 | Y14: 2 | Z14: 2 | AA14: 2 | AB14: 2 | AC14: 2 | AD14: 2 | AE14: 2 | AF14: 2 | AG14: 2 | AH14: 2 | AI14: 2 | AJ14: 2 | AK14: 2 | AL14: 2 | AM14: 2 | AN14: 2 | AO14: 2 | AP14: 2
A15: KB | B15: 6 | C15: 4 | D15: 5 | E15: 4 | F15: 5 | G15: 0 | H15: 5 | I15: 6 | J15: 5 | K15: 6 | L15: 5 | M15: 5 | N15: 6 | O15: 5 | P15: 6 | Q15: 5 | R15: 5 | S15: 6 | T15: 5 | U15: 6 | V15: 5 | W15: 5 | X15: 6 | Y15: 5 | Z15: 6 | AA15: 5 | AB15: 5 | AC15: 6 | AD15: 5 | AE15: 6 | AF15: 5 | AG15: 5 | AH15: 6 | AI15: 5 | AJ15: 6 | AK15: 5 | AL15: 4 | AM15: 5 | AN15: 4 | AO15: 5 | AP15: 4
A16: KG | B16: 8 | C16: 3 | D16: 3 | E16: 3 | F16: 3 | G16: 0 | H16: 4 | I16: 3 | J16: 4 | K16: 3 | L16: 4 | M16: 4 | N16: 4 | O16: 5 | P16: 4 | Q16: 4 | R16: 4 | S16: 4 | T16: 5 | U16: 4 | V16: 4 | W16: 4 | X16: 4 | Y16: 5 | Z16: 4 | AA16: 3 | AB16: 3 | AC16: 4 | AD16: 4 | AE16: 4 | AF16: 3 | AG16: 3 | AH16: 4 | AI16: 4 | AJ16: 4 | AK16: 3 | AL16: 3 | AM16: 4 | AN16: 4 | AO16: 4 | AP16: 3
... A21: Grand Total | B21: 110 | C21: 52 | D21: 55 | E21: 58 | F21: 54 | G21: 0 | H21: 70 | I21: 74 | J21: 78 | K21: 72 | L21: 66 | M21: 75 | N21: 78 | O21: 84 | P21: 76 | Q21: 71 | R21: 77 | S21: 80 | T21: 86 | U21: 78 | V21: 73 | W21: 77 | X21: 81 | Y21: 87 | Z21: 79 | AA21: 72 | AB21: 72 | AC21: 77 | AD21: 80 | AE21: 75 | AF21: 68 | AG21: 67 | AH21: 72 | AI21: 75 | AJ21: 72 | AK21: 64 | AL21: 58 | AM21: 61 | AN21: 65 | AO21: 61 | AP21: 56

Sheet bus priority

Sheet DD RR SS Trips
B1: Dillly Dally | C1: Romper Room | E1: Trips
D2: July
B3: Monday | C3: Tuesday | D3: Wednesday | E3: Thursday | F3: Friday
B4: 30 | C4: 1 | D4: 2 | E4: 3 | F4: 4
B5: 7 | C5: 8 | D5: 9 | E5: 10 | F5: 11
B6: 14 | C6: 15 | D6: 16 | E6: 17 | F6: 18
B7: 21 | C7: 22 | D7: 23 | E7: 24 | F7: 25
D9: August
B10: Monday | C10: Tuesday | D10: Wednesday | E10: Thursday | F10: Friday
B11: 28 | C11: 29 | D11: 30 | E11: 31 | F11: 1
B12: 4 | C12: 5 | D12: 6 | E12: 7 | F12: 8
B13: 11 | C13: 12 | D13: 13 | E13: 14 | F13: 15
B14: 18 | C14: 19 | D14: 20 | E14: 21 | F14: 22

Sheet DO NOT CHANGEFormula
B3: =COUNTA(B6:B379) -> 371 | C3: =COUNTA(C6:C379) -> 67
A4: Student ID | B4: Full Name | C4: Group | D4: 45897 | E4: =D4+1 -> 45898 | F4: =E4+1 -> 45899 | G4: =F4+1 -> 45900 | H4: =G4+1 -> 45901 | I4: =H4+1 -> 45902 | J4: =I4+1 -> 45903 | K4: =J4+1 -> 45904 | L4: =K4+1 -> 45905 | ... BP4: =BO4+1 -> 45961
A5: 5 | B5: ='2025'!D5 -> Gonzalez, Veronica | C5: ='2025'!H5 -> PK3.1 | D5: =IF(AND(AND(AND(D$4>='2025'!$L5,D$4<='2025'!$M5), D$4<>DATE(2025,7,4)), (SWITCH(weekday(D$4), 1, 0, 2, if(ISBLANK('2025'!$P5), 0, 1), 3, if(ISBLANK('2025'!$Q5), 0, 1), 4, if(ISBLANK('2025'!$R5), 0, 1), 5, if(ISBLANK('2025'!$S5), 0, 1), 6, if(ISBLANK('2025'!$T5), 0, 1), 7, 0))), 1, "") | E5: =IF(AND(AND(AND(E$4>='2025'!$L5,E$4<='2025'!$M5), E$4<>DATE(2025,7,4)), (SWITCH(weekday(E$4), 1, 0, 2, if(ISBLANK('2025'!$P5), 0, 1), 3, if(ISBLANK('2025'!$Q5), 0, 1), 4, if(ISBLANK('2025'!$R5), 0, 1), 5, if(ISBLANK('2025'!$S5), 0, 1), 6, if(ISBLANK('2025'!$T5), 0, 1), 7, 0))), 1, "") | F5: =IF(AND(AND(AND(F$4>='2025'!$L5,F$4<='2025'!$M5), F$4<>DATE(2025,7,4)), (SWITCH(weekday(F$4), 1, 0, 2, if(ISBLANK('2025'!$P5), 0, 1), 3, if(ISBLANK('2025'!$Q5), 0, 1), 4, if(ISBLANK('2025'!$R5), 0, 1), 5, if(ISBLANK('2025'!$S5), 0, 1), 6, if(ISBLANK('2025'!$T5), 0, 1), 7, 0))), 1, "") | G5: =IF(AND(AND(AND(G$4>='2025'!$L5,G$4<='2025'!$M5), G$4<>DATE(2025,7,4)), (SWITCH(weekday(G$4), 1, 0, 2, if(ISBLANK('2025'!$P5), 0, 1), 3, if(ISBLANK('2025'!$Q5), 0, 1), 4, if(ISBLANK('2025'!$R5), 0, 1), 5, if(ISBLANK('2025'!$S5), 0, 1), 6, if(ISBLANK('2025'!$T5), 0, 1), 7, 0))), 1, "") | H5: =IF(AND(AND(AND(H$4>='2025'!$L5,H$4<='2025'!$M5), H$4<>DATE(2025,7,4)), (SWITCH(weekday(H$4), 1, 0, 2, if(ISBLANK('2025'!$P5), 0, 1), 3, if(ISBLANK('2025'!$Q5), 0, 1), 4, if(ISBLANK('2025'!$R5), 0, 1), 5, if(ISBLANK('2025'!$S5), 0, 1), 6, if(ISBLANK('2025'!$T5), 0, 1), 7, 0))), 1, "") | I5: =IF(AND(AND(AND(I$4>='2025'!$L5,I$4<='2025'!$M5), I$4<>DATE(2025,7,4)), (SWITCH(weekday(I$4), 1, 0, 2, if(ISBLANK('2025'!$P5), 0, 1), 3, if(ISBLANK('2025'!$Q5), 0, 1), 4, if(ISBLANK('2025'!$R5), 0, 1), 5, if(ISBLANK('2025'!$S5), 0, 1), 6, if(ISBLANK('2025'!$T5), 0, 1), 7, 0))), 1, "") | J5: =IF(AND(AND(AND(J$4>='2025'!$L5,J$4<='2025'!$M5), J$4<>DATE(2025,7,4)), (SWITCH(weekday(J$4), 1, 0, 2, if(ISBLANK('2025'!$P5), 0, 1), 3, if(ISBLANK('2025'!$Q5), 0, 1), 4, if(ISBLANK('2025'!$R5), 0, 1), 5, if(ISBLANK('2025'!$S5), 0, 1), 6, if(ISBLANK('2025'!$T5), 0, 1), 7, 0))), 1, "") | K5: =IF(AND(AND(AND(K$4>='2025'!$L5,K$4<='2025'!$M5), K$4<>DATE(2025,7,4)), (SWITCH(weekday(K$4), 1, 0, 2, if(ISBLANK('2025'!$P5), 0, 1), 3, if(ISBLANK('2025'!$Q5), 0, 1), 4, if(ISBLANK('2025'!$R5), 0, 1), 5, if(ISBLANK('2025'!$S5), 0, 1), 6, if(ISBLANK('2025'!$T5), 0, 1), 7, 0))), 1, "") | ... BF5: =IF(AND(AND(AND(BF$4>='2025'!$L5,BF$4<='2025'!$M5), BF$4<>DATE(2025,7,4)), (SWITCH(weekday(BF$4), 1, 0, 2, if(ISBLANK('2025'!$P5), 0, 1), 3, if(ISBLANK('2025'!$Q5), 0, 1), 4, if(ISBLANK('2025'!$R5), 0, 1), 5, if(ISBLANK('2025'!$S5), 0, 1), 6, if(ISBLANK('2025'!$T5), 0, 1), 7, 0))), 1, "")
A6: =A5+1 -> 6 | B6: ='2025'!D6 -> Ho, Kyle | C6: ='2025'!H6 -> PK3 | D6: =IF(AND(AND(AND(D$4>='2025'!$L6,D$4<='2025'!$M6), D$4<>DATE(2025,7,4)), (SWITCH(weekday(D$4), 1, 0, 2, if(ISBLANK('2025'!$P6), 0, 1), 3, if(ISBLANK('2025'!$Q6), 0, 1), 4, if(ISBLANK('2025'!$R6), 0, 1), 5, if(ISBLANK('2025'!$S6), 0, 1), 6, if(ISBLANK('2025'!$T6), 0, 1), 7, 0))), 1, "") | E6: =IF(AND(AND(AND(E$4>='2025'!$L6,E$4<='2025'!$M6), E$4<>DATE(2025,7,4)), (SWITCH(weekday(E$4), 1, 0, 2, if(ISBLANK('2025'!$P6), 0, 1), 3, if(ISBLANK('2025'!$Q6), 0, 1), 4, if(ISBLANK('2025'!$R6), 0, 1), 5, if(ISBLANK('2025'!$S6), 0, 1), 6, if(ISBLANK('2025'!$T6), 0, 1), 7, 0))), 1, "") | F6: =IF(AND(AND(AND(F$4>='2025'!$L6,F$4<='2025'!$M6), F$4<>DATE(2025,7,4)), (SWITCH(weekday(F$4), 1, 0, 2, if(ISBLANK('2025'!$P6), 0, 1), 3, if(ISBLANK('2025'!$Q6), 0, 1), 4, if(ISBLANK('2025'!$R6), 0, 1), 5, if(ISBLANK('2025'!$S6), 0, 1), 6, if(ISBLANK('2025'!$T6), 0, 1), 7, 0))), 1, "") | G6: =IF(AND(AND(AND(G$4>='2025'!$L6,G$4<='2025'!$M6), G$4<>DATE(2025,7,4)), (SWITCH(weekday(G$4), 1, 0, 2, if(ISBLANK('2025'!$P6), 0, 1), 3, if(ISBLANK('2025'!$Q6), 0, 1), 4, if(ISBLANK('2025'!$R6), 0, 1), 5, if(ISBLANK('2025'!$S6), 0, 1), 6, if(ISBLANK('2025'!$T6), 0, 1), 7, 0))), 1, "") | H6: =IF(AND(AND(AND(H$4>='2025'!$L6,H$4<='2025'!$M6), H$4<>DATE(2025,7,4)), (SWITCH(weekday(H$4), 1, 0, 2, if(ISBLANK('2025'!$P6), 0, 1), 3, if(ISBLANK('2025'!$Q6), 0, 1), 4, if(ISBLANK('2025'!$R6), 0, 1), 5, if(ISBLANK('2025'!$S6), 0, 1), 6, if(ISBLANK('2025'!$T6), 0, 1), 7, 0))), 1, "") | I6: =IF(AND(AND(AND(I$4>='2025'!$L6,I$4<='2025'!$M6), I$4<>DATE(2025,7,4)), (SWITCH(weekday(I$4), 1, 0, 2, if(ISBLANK('2025'!$P6), 0, 1), 3, if(ISBLANK('2025'!$Q6), 0, 1), 4, if(ISBLANK('2025'!$R6), 0, 1), 5, if(ISBLANK('2025'!$S6), 0, 1), 6, if(ISBLANK('2025'!$T6), 0, 1), 7, 0))), 1, "") | J6: =IF(AND(AND(AND(J$4>='2025'!$L6,J$4<='2025'!$M6), J$4<>DATE(2025,7,4)), (SWITCH(weekday(J$4), 1, 0, 2, if(ISBLANK('2025'!$P6), 0, 1), 3, if(ISBLANK('2025'!$Q6), 0, 1), 4, if(ISBLANK('2025'!$R6), 0, 1), 5, if(ISBLANK('2025'!$S6), 0, 1), 6, if(ISBLANK('2025'!$T6), 0, 1), 7, 0))), 1, "") | K6: =IF(AND(AND(AND(K$4>='2025'!$L6,K$4<='2025'!$M6), K$4<>DATE(2025,7,4)), (SWITCH(weekday(K$4), 1, 0, 2, if(ISBLANK('2025'!$P6), 0, 1), 3, if(ISBLANK('2025'!$Q6), 0, 1), 4, if(ISBLANK('2025'!$R6), 0, 1), 5, if(ISBLANK('2025'!$S6), 0, 1), 6, if(ISBLANK('2025'!$T6), 0, 1), 7, 0))), 1, "") | ... BF6: =IF(AND(AND(AND(BF$4>='2025'!$L6,BF$4<='2025'!$M6), BF$4<>DATE(2025,7,4)), (SWITCH(weekday(BF$4), 1, 0, 2, if(ISBLANK('2025'!$P6), 0, 1), 3, if(ISBLANK('2025'!$Q6), 0, 1), 4, if(ISBLANK('2025'!$R6), 0, 1), 5, if(ISBLANK('2025'!$S6), 0, 1), 6, if(ISBLANK('2025'!$T6), 0, 1), 7, 0))), 1, "")
A7: =A6+1 -> 7 | B7: ='2025'!D7 -> Zhao, Isaac | C7: ='2025'!H7 -> PK3.1 | D7: =IF(AND(AND(AND(D$4>='2025'!$L7,D$4<='2025'!$M7), D$4<>DATE(2025,7,4)), (SWITCH(weekday(D$4), 1, 0, 2, if(ISBLANK('2025'!$P7), 0, 1), 3, if(ISBLANK('2025'!$Q7), 0, 1), 4, if(ISBLANK('2025'!$R7), 0, 1), 5, if(ISBLANK('2025'!$S7), 0, 1), 6, if(ISBLANK('2025'!$T7), 0, 1), 7, 0))), 1, "") | E7: =IF(AND(AND(AND(E$4>='2025'!$L7,E$4<='2025'!$M7), E$4<>DATE(2025,7,4)), (SWITCH(weekday(E$4), 1, 0, 2, if(ISBLANK('2025'!$P7), 0, 1), 3, if(ISBLANK('2025'!$Q7), 0, 1), 4, if(ISBLANK('2025'!$R7), 0, 1), 5, if(ISBLANK('2025'!$S7), 0, 1), 6, if(ISBLANK('2025'!$T7), 0, 1), 7, 0))), 1, "") | F7: =IF(AND(AND(AND(F$4>='2025'!$L7,F$4<='2025'!$M7), F$4<>DATE(2025,7,4)), (SWITCH(weekday(F$4), 1, 0, 2, if(ISBLANK('2025'!$P7), 0, 1), 3, if(ISBLANK('2025'!$Q7), 0, 1), 4, if(ISBLANK('2025'!$R7), 0, 1), 5, if(ISBLANK('2025'!$S7), 0, 1), 6, if(ISBLANK('2025'!$T7), 0, 1), 7, 0))), 1, "") | G7: =IF(AND(AND(AND(G$4>='2025'!$L7,G$4<='2025'!$M7), G$4<>DATE(2025,7,4)), (SWITCH(weekday(G$4), 1, 0, 2, if(ISBLANK('2025'!$P7), 0, 1), 3, if(ISBLANK('2025'!$Q7), 0, 1), 4, if(ISBLANK('2025'!$R7), 0, 1), 5, if(ISBLANK('2025'!$S7), 0, 1), 6, if(ISBLANK('2025'!$T7), 0, 1), 7, 0))), 1, "") | H7: =IF(AND(AND(AND(H$4>='2025'!$L7,H$4<='2025'!$M7), H$4<>DATE(2025,7,4)), (SWITCH(weekday(H$4), 1, 0, 2, if(ISBLANK('2025'!$P7), 0, 1), 3, if(ISBLANK('2025'!$Q7), 0, 1), 4, if(ISBLANK('2025'!$R7), 0, 1), 5, if(ISBLANK('2025'!$S7), 0, 1), 6, if(ISBLANK('2025'!$T7), 0, 1), 7, 0))), 1, "") | I7: =IF(AND(AND(AND(I$4>='2025'!$L7,I$4<='2025'!$M7), I$4<>DATE(2025,7,4)), (SWITCH(weekday(I$4), 1, 0, 2, if(ISBLANK('2025'!$P7), 0, 1), 3, if(ISBLANK('2025'!$Q7), 0, 1), 4, if(ISBLANK('2025'!$R7), 0, 1), 5, if(ISBLANK('2025'!$S7), 0, 1), 6, if(ISBLANK('2025'!$T7), 0, 1), 7, 0))), 1, "") | J7: =IF(AND(AND(AND(J$4>='2025'!$L7,J$4<='2025'!$M7), J$4<>DATE(2025,7,4)), (SWITCH(weekday(J$4), 1, 0, 2, if(ISBLANK('2025'!$P7), 0, 1), 3, if(ISBLANK('2025'!$Q7), 0, 1), 4, if(ISBLANK('2025'!$R7), 0, 1), 5, if(ISBLANK('2025'!$S7), 0, 1), 6, if(ISBLANK('2025'!$T7), 0, 1), 7, 0))), 1, "") | K7: =IF(AND(AND(AND(K$4>='2025'!$L7,K$4<='2025'!$M7), K$4<>DATE(2025,7,4)), (SWITCH(weekday(K$4), 1, 0, 2, if(ISBLANK('2025'!$P7), 0, 1), 3, if(ISBLANK('2025'!$Q7), 0, 1), 4, if(ISBLANK('2025'!$R7), 0, 1), 5, if(ISBLANK('2025'!$S7), 0, 1), 6, if(ISBLANK('2025'!$T7), 0, 1), 7, 0))), 1, "") | ... BF7: =IF(AND(AND(AND(BF$4>='2025'!$L7,BF$4<='2025'!$M7), BF$4<>DATE(2025,7,4)), (SWITCH(weekday(BF$4), 1, 0, 2, if(ISBLANK('2025'!$P7), 0, 1), 3, if(ISBLANK('2025'!$Q7), 0, 1), 4, if(ISBLANK('2025'!$R7), 0, 1), 5, if(ISBLANK('2025'!$S7), 0, 1), 6, if(ISBLANK('2025'!$T7), 0, 1), 7, 0))), 1, "")
A8: =A7+1 -> 8 | B8: ='2025'!D8 -> shah, ayan | C8: ='2025'!H8 -> PK3 | D8: =IF(AND(AND(AND(D$4>='2025'!$L8,D$4<='2025'!$M8), D$4<>DATE(2025,7,4)), (SWITCH(weekday(D$4), 1, 0, 2, if(ISBLANK('2025'!$P8), 0, 1), 3, if(ISBLANK('2025'!$Q8), 0, 1), 4, if(ISBLANK('2025'!$R8), 0, 1), 5, if(ISBLANK('2025'!$S8), 0, 1), 6, if(ISBLANK('2025'!$T8), 0, 1), 7, 0))), 1, "") | E8: =IF(AND(AND(AND(E$4>='2025'!$L8,E$4<='2025'!$M8), E$4<>DATE(2025,7,4)), (SWITCH(weekday(E$4), 1, 0, 2, if(ISBLANK('2025'!$P8), 0, 1), 3, if(ISBLANK('2025'!$Q8), 0, 1), 4, if(ISBLANK('2025'!$R8), 0, 1), 5, if(ISBLANK('2025'!$S8), 0, 1), 6, if(ISBLANK('2025'!$T8), 0, 1), 7, 0))), 1, "") | F8: =IF(AND(AND(AND(F$4>='2025'!$L8,F$4<='2025'!$M8), F$4<>DATE(2025,7,4)), (SWITCH(weekday(F$4), 1, 0, 2, if(ISBLANK('2025'!$P8), 0, 1), 3, if(ISBLANK('2025'!$Q8), 0, 1), 4, if(ISBLANK('2025'!$R8), 0, 1), 5, if(ISBLANK('2025'!$S8), 0, 1), 6, if(ISBLANK('2025'!$T8), 0, 1), 7, 0))), 1, "") | G8: =IF(AND(AND(AND(G$4>='2025'!$L8,G$4<='2025'!$M8), G$4<>DATE(2025,7,4)), (SWITCH(weekday(G$4), 1, 0, 2, if(ISBLANK('2025'!$P8), 0, 1), 3, if(ISBLANK('2025'!$Q8), 0, 1), 4, if(ISBLANK('2025'!$R8), 0, 1), 5, if(ISBLANK('2025'!$S8), 0, 1), 6, if(ISBLANK('2025'!$T8), 0, 1), 7, 0))), 1, "") | H8: =IF(AND(AND(AND(H$4>='2025'!$L8,H$4<='2025'!$M8), H$4<>DATE(2025,7,4)), (SWITCH(weekday(H$4), 1, 0, 2, if(ISBLANK('2025'!$P8), 0, 1), 3, if(ISBLANK('2025'!$Q8), 0, 1), 4, if(ISBLANK('2025'!$R8), 0, 1), 5, if(ISBLANK('2025'!$S8), 0, 1), 6, if(ISBLANK('2025'!$T8), 0, 1), 7, 0))), 1, "") | I8: =IF(AND(AND(AND(I$4>='2025'!$L8,I$4<='2025'!$M8), I$4<>DATE(2025,7,4)), (SWITCH(weekday(I$4), 1, 0, 2, if(ISBLANK('2025'!$P8), 0, 1), 3, if(ISBLANK('2025'!$Q8), 0, 1), 4, if(ISBLANK('2025'!$R8), 0, 1), 5, if(ISBLANK('2025'!$S8), 0, 1), 6, if(ISBLANK('2025'!$T8), 0, 1), 7, 0))), 1, "") | J8: =IF(AND(AND(AND(J$4>='2025'!$L8,J$4<='2025'!$M8), J$4<>DATE(2025,7,4)), (SWITCH(weekday(J$4), 1, 0, 2, if(ISBLANK('2025'!$P8), 0, 1), 3, if(ISBLANK('2025'!$Q8), 0, 1), 4, if(ISBLANK('2025'!$R8), 0, 1), 5, if(ISBLANK('2025'!$S8), 0, 1), 6, if(ISBLANK('2025'!$T8), 0, 1), 7, 0))), 1, "") | K8: =IF(AND(AND(AND(K$4>='2025'!$L8,K$4<='2025'!$M8), K$4<>DATE(2025,7,4)), (SWITCH(weekday(K$4), 1, 0, 2, if(ISBLANK('2025'!$P8), 0, 1), 3, if(ISBLANK('2025'!$Q8), 0, 1), 4, if(ISBLANK('2025'!$R8), 0, 1), 5, if(ISBLANK('2025'!$S8), 0, 1), 6, if(ISBLANK('2025'!$T8), 0, 1), 7, 0))), 1, "") | ... BF8: =IF(AND(AND(AND(BF$4>='2025'!$L8,BF$4<='2025'!$M8), BF$4<>DATE(2025,7,4)), (SWITCH(weekday(BF$4), 1, 0, 2, if(ISBLANK('2025'!$P8), 0, 1), 3, if(ISBLANK('2025'!$Q8), 0, 1), 4, if(ISBLANK('2025'!$R8), 0, 1), 5, if(ISBLANK('2025'!$S8), 0, 1), 6, if(ISBLANK('2025'!$T8), 0, 1), 7, 0))), 1, "")
A9: =A8+1 -> 9 | B9: ='2025'!D9 -> o connell, finnula | C9: ='2025'!H9 -> PK3 | D9: =IF(AND(AND(AND(D$4>='2025'!$L9,D$4<='2025'!$M9), D$4<>DATE(2025,7,4)), (SWITCH(weekday(D$4), 1, 0, 2, if(ISBLANK('2025'!$P9), 0, 1), 3, if(ISBLANK('2025'!$Q9), 0, 1), 4, if(ISBLANK('2025'!$R9), 0, 1), 5, if(ISBLANK('2025'!$S9), 0, 1), 6, if(ISBLANK('2025'!$T9), 0, 1), 7, 0))), 1, "") | E9: =IF(AND(AND(AND(E$4>='2025'!$L9,E$4<='2025'!$M9), E$4<>DATE(2025,7,4)), (SWITCH(weekday(E$4), 1, 0, 2, if(ISBLANK('2025'!$P9), 0, 1), 3, if(ISBLANK('2025'!$Q9), 0, 1), 4, if(ISBLANK('2025'!$R9), 0, 1), 5, if(ISBLANK('2025'!$S9), 0, 1), 6, if(ISBLANK('2025'!$T9), 0, 1), 7, 0))), 1, "") | F9: =IF(AND(AND(AND(F$4>='2025'!$L9,F$4<='2025'!$M9), F$4<>DATE(2025,7,4)), (SWITCH(weekday(F$4), 1, 0, 2, if(ISBLANK('2025'!$P9), 0, 1), 3, if(ISBLANK('2025'!$Q9), 0, 1), 4, if(ISBLANK('2025'!$R9), 0, 1), 5, if(ISBLANK('2025'!$S9), 0, 1), 6, if(ISBLANK('2025'!$T9), 0, 1), 7, 0))), 1, "") | G9: =IF(AND(AND(AND(G$4>='2025'!$L9,G$4<='2025'!$M9), G$4<>DATE(2025,7,4)), (SWITCH(weekday(G$4), 1, 0, 2, if(ISBLANK('2025'!$P9), 0, 1), 3, if(ISBLANK('2025'!$Q9), 0, 1), 4, if(ISBLANK('2025'!$R9), 0, 1), 5, if(ISBLANK('2025'!$S9), 0, 1), 6, if(ISBLANK('2025'!$T9), 0, 1), 7, 0))), 1, "") | H9: =IF(AND(AND(AND(H$4>='2025'!$L9,H$4<='2025'!$M9), H$4<>DATE(2025,7,4)), (SWITCH(weekday(H$4), 1, 0, 2, if(ISBLANK('2025'!$P9), 0, 1), 3, if(ISBLANK('2025'!$Q9), 0, 1), 4, if(ISBLANK('2025'!$R9), 0, 1), 5, if(ISBLANK('2025'!$S9), 0, 1), 6, if(ISBLANK('2025'!$T9), 0, 1), 7, 0))), 1, "") | I9: =IF(AND(AND(AND(I$4>='2025'!$L9,I$4<='2025'!$M9), I$4<>DATE(2025,7,4)), (SWITCH(weekday(I$4), 1, 0, 2, if(ISBLANK('2025'!$P9), 0, 1), 3, if(ISBLANK('2025'!$Q9), 0, 1), 4, if(ISBLANK('2025'!$R9), 0, 1), 5, if(ISBLANK('2025'!$S9), 0, 1), 6, if(ISBLANK('2025'!$T9), 0, 1), 7, 0))), 1, "") | J9: =IF(AND(AND(AND(J$4>='2025'!$L9,J$4<='2025'!$M9), J$4<>DATE(2025,7,4)), (SWITCH(weekday(J$4), 1, 0, 2, if(ISBLANK('2025'!$P9), 0, 1), 3, if(ISBLANK('2025'!$Q9), 0, 1), 4, if(ISBLANK('2025'!$R9), 0, 1), 5, if(ISBLANK('2025'!$S9), 0, 1), 6, if(ISBLANK('2025'!$T9), 0, 1), 7, 0))), 1, "") | K9: =IF(AND(AND(AND(K$4>='2025'!$L9,K$4<='2025'!$M9), K$4<>DATE(2025,7,4)), (SWITCH(weekday(K$4), 1, 0, 2, if(ISBLANK('2025'!$P9), 0, 1), 3, if(ISBLANK('2025'!$Q9), 0, 1), 4, if(ISBLANK('2025'!$R9), 0, 1), 5, if(ISBLANK('2025'!$S9), 0, 1), 6, if(ISBLANK('2025'!$T9), 0, 1), 7, 0))), 1, "") | ... BF9: =IF(AND(AND(AND(BF$4>='2025'!$L9,BF$4<='2025'!$M9), BF$4<>DATE(2025,7,4)), (SWITCH(weekday(BF$4), 1, 0, 2, if(ISBLANK('2025'!$P9), 0, 1), 3, if(ISBLANK('2025'!$Q9), 0, 1), 4, if(ISBLANK('2025'!$R9), 0, 1), 5, if(ISBLANK('2025'!$S9), 0, 1), 6, if(ISBLANK('2025'!$T9), 0, 1), 7, 0))), 1, "")
A10: =A9+1 -> 10 | B10: ='2025'!D10 -> leung, sequoia | C10: ='2025'!H10 -> PK3 | D10: =IF(AND(AND(AND(D$4>='2025'!$L10,D$4<='2025'!$M10), D$4<>DATE(2025,7,4)), (SWITCH(weekday(D$4), 1, 0, 2, if(ISBLANK('2025'!$P10), 0, 1), 3, if(ISBLANK('2025'!$Q10), 0, 1), 4, if(ISBLANK('2025'!$R10), 0, 1), 5, if(ISBLANK('2025'!$S10), 0, 1), 6, if(ISBLANK('2025'!$T10), 0, 1), 7, 0))), 1, "") -> 1 | E10: =IF(AND(AND(AND(E$4>='2025'!$L10,E$4<='2025'!$M10), E$4<>DATE(2025,7,4)), (SWITCH(weekday(E$4), 1, 0, 2, if(ISBLANK('2025'!$P10), 0, 1), 3, if(ISBLANK('2025'!$Q10), 0, 1), 4, if(ISBLANK('2025'!$R10), 0, 1), 5, if(ISBLANK('2025'!$S10), 0, 1), 6, if(ISBLANK('2025'!$T10), 0, 1), 7, 0))), 1, "") -> 1 | F10: =IF(AND(AND(AND(F$4>='2025'!$L10,F$4<='2025'!$M10), F$4<>DATE(2025,7,4)), (SWITCH(weekday(F$4), 1, 0, 2, if(ISBLANK('2025'!$P10), 0, 1), 3, if(ISBLANK('2025'!$Q10), 0, 1), 4, if(ISBLANK('2025'!$R10), 0, 1), 5, if(ISBLANK('2025'!$S10), 0, 1), 6, if(ISBLANK('2025'!$T10), 0, 1), 7, 0))), 1, "") | G10: =IF(AND(AND(AND(G$4>='2025'!$L10,G$4<='2025'!$M10), G$4<>DATE(2025,7,4)), (SWITCH(weekday(G$4), 1, 0, 2, if(ISBLANK('2025'!$P10), 0, 1), 3, if(ISBLANK('2025'!$Q10), 0, 1), 4, if(ISBLANK('2025'!$R10), 0, 1), 5, if(ISBLANK('2025'!$S10), 0, 1), 6, if(ISBLANK('2025'!$T10), 0, 1), 7, 0))), 1, "") | H10: =IF(AND(AND(AND(H$4>='2025'!$L10,H$4<='2025'!$M10), H$4<>DATE(2025,7,4)), (SWITCH(weekday(H$4), 1, 0, 2, if(ISBLANK('2025'!$P10), 0, 1), 3, if(ISBLANK('2025'!$Q10), 0, 1), 4, if(ISBLANK('2025'!$R10), 0, 1), 5, if(ISBLANK('2025'!$S10), 0, 1), 6, if(ISBLANK('2025'!$T10), 0, 1), 7, 0))), 1, "") -> 1 | I10: =IF(AND(AND(AND(I$4>='2025'!$L10,I$4<='2025'!$M10), I$4<>DATE(2025,7,4)), (SWITCH(weekday(I$4), 1, 0, 2, if(ISBLANK('2025'!$P10), 0, 1), 3, if(ISBLANK('2025'!$Q10), 0, 1), 4, if(ISBLANK('2025'!$R10), 0, 1), 5, if(ISBLANK('2025'!$S10), 0, 1), 6, if(ISBLANK('2025'!$T10), 0, 1), 7, 0))), 1, "") -> 1 | J10: =IF(AND(AND(AND(J$4>='2025'!$L10,J$4<='2025'!$M10), J$4<>DATE(2025,7,4)), (SWITCH(weekday(J$4), 1, 0, 2, if(ISBLANK('2025'!$P10), 0, 1), 3, if(ISBLANK('2025'!$Q10), 0, 1), 4, if(ISBLANK('2025'!$R10), 0, 1), 5, if(ISBLANK('2025'!$S10), 0, 1), 6, if(ISBLANK('2025'!$T10), 0, 1), 7, 0))), 1, "") -> 1 | K10: =IF(AND(AND(AND(K$4>='2025'!$L10,K$4<='2025'!$M10), K$4<>DATE(2025,7,4)), (SWITCH(weekday(K$4), 1, 0, 2, if(ISBLANK('2025'!$P10), 0, 1), 3, if(ISBLANK('2025'!$Q10), 0, 1), 4, if(ISBLANK('2025'!$R10), 0, 1), 5, if(ISBLANK('2025'!$S10), 0, 1), 6, if(ISBLANK('2025'!$T10), 0, 1), 7, 0))), 1, "") -> 1 | ... BF10: =IF(AND(AND(AND(BF$4>='2025'!$L10,BF$4<='2025'!$M10), BF$4<>DATE(2025,7,4)), (SWITCH(weekday(BF$4), 1, 0, 2, if(ISBLANK('2025'!$P10), 0, 1), 3, if(ISBLANK('2025'!$Q10), 0, 1), 4, if(ISBLANK('2025'!$R10), 0, 1), 5, if(ISBLANK('2025'!$S10), 0, 1), 6, if(ISBLANK('2025'!$T10), 0, 1), 7, 0))), 1, "") -> 1
A11: =A10+1 -> 11 | B11: ='2025'!D11 -> Salazar, Dylan | C11: ='2025'!H11 -> PK3.1 | D11: =IF(AND(AND(AND(D$4>='2025'!$L11,D$4<='2025'!$M11), D$4<>DATE(2025,7,4)), (SWITCH(weekday(D$4), 1, 0, 2, if(ISBLANK('2025'!$P11), 0, 1), 3, if(ISBLANK('2025'!$Q11), 0, 1), 4, if(ISBLANK('2025'!$R11), 0, 1), 5, if(ISBLANK('2025'!$S11), 0, 1), 6, if(ISBLANK('2025'!$T11), 0, 1), 7, 0))), 1, "") | E11: =IF(AND(AND(AND(E$4>='2025'!$L11,E$4<='2025'!$M11), E$4<>DATE(2025,7,4)), (SWITCH(weekday(E$4), 1, 0, 2, if(ISBLANK('2025'!$P11), 0, 1), 3, if(ISBLANK('2025'!$Q11), 0, 1), 4, if(ISBLANK('2025'!$R11), 0, 1), 5, if(ISBLANK('2025'!$S11), 0, 1), 6, if(ISBLANK('2025'!$T11), 0, 1), 7, 0))), 1, "") | F11: =IF(AND(AND(AND(F$4>='2025'!$L11,F$4<='2025'!$M11), F$4<>DATE(2025,7,4)), (SWITCH(weekday(F$4), 1, 0, 2, if(ISBLANK('2025'!$P11), 0, 1), 3, if(ISBLANK('2025'!$Q11), 0, 1), 4, if(ISBLANK('2025'!$R11), 0, 1), 5, if(ISBLANK('2025'!$S11), 0, 1), 6, if(ISBLANK('2025'!$T11), 0, 1), 7, 0))), 1, "") | G11: =IF(AND(AND(AND(G$4>='2025'!$L11,G$4<='2025'!$M11), G$4<>DATE(2025,7,4)), (SWITCH(weekday(G$4), 1, 0, 2, if(ISBLANK('2025'!$P11), 0, 1), 3, if(ISBLANK('2025'!$Q11), 0, 1), 4, if(ISBLANK('2025'!$R11), 0, 1), 5, if(ISBLANK('2025'!$S11), 0, 1), 6, if(ISBLANK('2025'!$T11), 0, 1), 7, 0))), 1, "") | H11: =IF(AND(AND(AND(H$4>='2025'!$L11,H$4<='2025'!$M11), H$4<>DATE(2025,7,4)), (SWITCH(weekday(H$4), 1, 0, 2, if(ISBLANK('2025'!$P11), 0, 1), 3, if(ISBLANK('2025'!$Q11), 0, 1), 4, if(ISBLANK('2025'!$R11), 0, 1), 5, if(ISBLANK('2025'!$S11), 0, 1), 6, if(ISBLANK('2025'!$T11), 0, 1), 7, 0))), 1, "") | I11: =IF(AND(AND(AND(I$4>='2025'!$L11,I$4<='2025'!$M11), I$4<>DATE(2025,7,4)), (SWITCH(weekday(I$4), 1, 0, 2, if(ISBLANK('2025'!$P11), 0, 1), 3, if(ISBLANK('2025'!$Q11), 0, 1), 4, if(ISBLANK('2025'!$R11), 0, 1), 5, if(ISBLANK('2025'!$S11), 0, 1), 6, if(ISBLANK('2025'!$T11), 0, 1), 7, 0))), 1, "") | J11: =IF(AND(AND(AND(J$4>='2025'!$L11,J$4<='2025'!$M11), J$4<>DATE(2025,7,4)), (SWITCH(weekday(J$4), 1, 0, 2, if(ISBLANK('2025'!$P11), 0, 1), 3, if(ISBLANK('2025'!$Q11), 0, 1), 4, if(ISBLANK('2025'!$R11), 0, 1), 5, if(ISBLANK('2025'!$S11), 0, 1), 6, if(ISBLANK('2025'!$T11), 0, 1), 7, 0))), 1, "") | K11: =IF(AND(AND(AND(K$4>='2025'!$L11,K$4<='2025'!$M11), K$4<>DATE(2025,7,4)), (SWITCH(weekday(K$4), 1, 0, 2, if(ISBLANK('2025'!$P11), 0, 1), 3, if(ISBLANK('2025'!$Q11), 0, 1), 4, if(ISBLANK('2025'!$R11), 0, 1), 5, if(ISBLANK('2025'!$S11), 0, 1), 6, if(ISBLANK('2025'!$T11), 0, 1), 7, 0))), 1, "") | ... BF11: =IF(AND(AND(AND(BF$4>='2025'!$L11,BF$4<='2025'!$M11), BF$4<>DATE(2025,7,4)), (SWITCH(weekday(BF$4), 1, 0, 2, if(ISBLANK('2025'!$P11), 0, 1), 3, if(ISBLANK('2025'!$Q11), 0, 1), 4, if(ISBLANK('2025'!$R11), 0, 1), 5, if(ISBLANK('2025'!$S11), 0, 1), 6, if(ISBLANK('2025'!$T11), 0, 1), 7, 0))), 1, "")
A12: =A11+1 -> 12 | B12: ='2025'!D12 -> Salazar, Alex | C12: ='2025'!H12 -> PK3.1 | D12: =IF(AND(AND(AND(D$4>='2025'!$L12,D$4<='2025'!$M12), D$4<>DATE(2025,7,4)), (SWITCH(weekday(D$4), 1, 0, 2, if(ISBLANK('2025'!$P12), 0, 1), 3, if(ISBLANK('2025'!$Q12), 0, 1), 4, if(ISBLANK('2025'!$R12), 0, 1), 5, if(ISBLANK('2025'!$S12), 0, 1), 6, if(ISBLANK('2025'!$T12), 0, 1), 7, 0))), 1, "") | E12: =IF(AND(AND(AND(E$4>='2025'!$L12,E$4<='2025'!$M12), E$4<>DATE(2025,7,4)), (SWITCH(weekday(E$4), 1, 0, 2, if(ISBLANK('2025'!$P12), 0, 1), 3, if(ISBLANK('2025'!$Q12), 0, 1), 4, if(ISBLANK('2025'!$R12), 0, 1), 5, if(ISBLANK('2025'!$S12), 0, 1), 6, if(ISBLANK('2025'!$T12), 0, 1), 7, 0))), 1, "") | F12: =IF(AND(AND(AND(F$4>='2025'!$L12,F$4<='2025'!$M12), F$4<>DATE(2025,7,4)), (SWITCH(weekday(F$4), 1, 0, 2, if(ISBLANK('2025'!$P12), 0, 1), 3, if(ISBLANK('2025'!$Q12), 0, 1), 4, if(ISBLANK('2025'!$R12), 0, 1), 5, if(ISBLANK('2025'!$S12), 0, 1), 6, if(ISBLANK('2025'!$T12), 0, 1), 7, 0))), 1, "") | G12: =IF(AND(AND(AND(G$4>='2025'!$L12,G$4<='2025'!$M12), G$4<>DATE(2025,7,4)), (SWITCH(weekday(G$4), 1, 0, 2, if(ISBLANK('2025'!$P12), 0, 1), 3, if(ISBLANK('2025'!$Q12), 0, 1), 4, if(ISBLANK('2025'!$R12), 0, 1), 5, if(ISBLANK('2025'!$S12), 0, 1), 6, if(ISBLANK('2025'!$T12), 0, 1), 7, 0))), 1, "") | H12: =IF(AND(AND(AND(H$4>='2025'!$L12,H$4<='2025'!$M12), H$4<>DATE(2025,7,4)), (SWITCH(weekday(H$4), 1, 0, 2, if(ISBLANK('2025'!$P12), 0, 1), 3, if(ISBLANK('2025'!$Q12), 0, 1), 4, if(ISBLANK('2025'!$R12), 0, 1), 5, if(ISBLANK('2025'!$S12), 0, 1), 6, if(ISBLANK('2025'!$T12), 0, 1), 7, 0))), 1, "") | I12: =IF(AND(AND(AND(I$4>='2025'!$L12,I$4<='2025'!$M12), I$4<>DATE(2025,7,4)), (SWITCH(weekday(I$4), 1, 0, 2, if(ISBLANK('2025'!$P12), 0, 1), 3, if(ISBLANK('2025'!$Q12), 0, 1), 4, if(ISBLANK('2025'!$R12), 0, 1), 5, if(ISBLANK('2025'!$S12), 0, 1), 6, if(ISBLANK('2025'!$T12), 0, 1), 7, 0))), 1, "") | J12: =IF(AND(AND(AND(J$4>='2025'!$L12,J$4<='2025'!$M12), J$4<>DATE(2025,7,4)), (SWITCH(weekday(J$4), 1, 0, 2, if(ISBLANK('2025'!$P12), 0, 1), 3, if(ISBLANK('2025'!$Q12), 0, 1), 4, if(ISBLANK('2025'!$R12), 0, 1), 5, if(ISBLANK('2025'!$S12), 0, 1), 6, if(ISBLANK('2025'!$T12), 0, 1), 7, 0))), 1, "") | K12: =IF(AND(AND(AND(K$4>='2025'!$L12,K$4<='2025'!$M12), K$4<>DATE(2025,7,4)), (SWITCH(weekday(K$4), 1, 0, 2, if(ISBLANK('2025'!$P12), 0, 1), 3, if(ISBLANK('2025'!$Q12), 0, 1), 4, if(ISBLANK('2025'!$R12), 0, 1), 5, if(ISBLANK('2025'!$S12), 0, 1), 6, if(ISBLANK('2025'!$T12), 0, 1), 7, 0))), 1, "") | ... BF12: =IF(AND(AND(AND(BF$4>='2025'!$L12,BF$4<='2025'!$M12), BF$4<>DATE(2025,7,4)), (SWITCH(weekday(BF$4), 1, 0, 2, if(ISBLANK('2025'!$P12), 0, 1), 3, if(ISBLANK('2025'!$Q12), 0, 1), 4, if(ISBLANK('2025'!$R12), 0, 1), 5, if(ISBLANK('2025'!$S12), 0, 1), 6, if(ISBLANK('2025'!$T12), 0, 1), 7, 0))), 1, "")
A13: =A12+1 -> 13 | B13: ='2025'!D13 -> Lung, Wesley | C13: ='2025'!H13 -> TOD | D13: =IF(AND(AND(AND(D$4>='2025'!$L13,D$4<='2025'!$M13), D$4<>DATE(2025,7,4)), (SWITCH(weekday(D$4), 1, 0, 2, if(ISBLANK('2025'!$P13), 0, 1), 3, if(ISBLANK('2025'!$Q13), 0, 1), 4, if(ISBLANK('2025'!$R13), 0, 1), 5, if(ISBLANK('2025'!$S13), 0, 1), 6, if(ISBLANK('2025'!$T13), 0, 1), 7, 0))), 1, "") -> 1 | E13: =IF(AND(AND(AND(E$4>='2025'!$L13,E$4<='2025'!$M13), E$4<>DATE(2025,7,4)), (SWITCH(weekday(E$4), 1, 0, 2, if(ISBLANK('2025'!$P13), 0, 1), 3, if(ISBLANK('2025'!$Q13), 0, 1), 4, if(ISBLANK('2025'!$R13), 0, 1), 5, if(ISBLANK('2025'!$S13), 0, 1), 6, if(ISBLANK('2025'!$T13), 0, 1), 7, 0))), 1, "") -> 1 | F13: =IF(AND(AND(AND(F$4>='2025'!$L13,F$4<='2025'!$M13), F$4<>DATE(2025,7,4)), (SWITCH(weekday(F$4), 1, 0, 2, if(ISBLANK('2025'!$P13), 0, 1), 3, if(ISBLANK('2025'!$Q13), 0, 1), 4, if(ISBLANK('2025'!$R13), 0, 1), 5, if(ISBLANK('2025'!$S13), 0, 1), 6, if(ISBLANK('2025'!$T13), 0, 1), 7, 0))), 1, "") | G13: =IF(AND(AND(AND(G$4>='2025'!$L13,G$4<='2025'!$M13), G$4<>DATE(2025,7,4)), (SWITCH(weekday(G$4), 1, 0, 2, if(ISBLANK('2025'!$P13), 0, 1), 3, if(ISBLANK('2025'!$Q13), 0, 1), 4, if(ISBLANK('2025'!$R13), 0, 1), 5, if(ISBLANK('2025'!$S13), 0, 1), 6, if(ISBLANK('2025'!$T13), 0, 1), 7, 0))), 1, "") | H13: =IF(AND(AND(AND(H$4>='2025'!$L13,H$4<='2025'!$M13), H$4<>DATE(2025,7,4)), (SWITCH(weekday(H$4), 1, 0, 2, if(ISBLANK('2025'!$P13), 0, 1), 3, if(ISBLANK('2025'!$Q13), 0, 1), 4, if(ISBLANK('2025'!$R13), 0, 1), 5, if(ISBLANK('2025'!$S13), 0, 1), 6, if(ISBLANK('2025'!$T13), 0, 1), 7, 0))), 1, "") -> 1 | I13: =IF(AND(AND(AND(I$4>='2025'!$L13,I$4<='2025'!$M13), I$4<>DATE(2025,7,4)), (SWITCH(weekday(I$4), 1, 0, 2, if(ISBLANK('2025'!$P13), 0, 1), 3, if(ISBLANK('2025'!$Q13), 0, 1), 4, if(ISBLANK('2025'!$R13), 0, 1), 5, if(ISBLANK('2025'!$S13), 0, 1), 6, if(ISBLANK('2025'!$T13), 0, 1), 7, 0))), 1, "") -> 1 | J13: =IF(AND(AND(AND(J$4>='2025'!$L13,J$4<='2025'!$M13), J$4<>DATE(2025,7,4)), (SWITCH(weekday(J$4), 1, 0, 2, if(ISBLANK('2025'!$P13), 0, 1), 3, if(ISBLANK('2025'!$Q13), 0, 1), 4, if(ISBLANK('2025'!$R13), 0, 1), 5, if(ISBLANK('2025'!$S13), 0, 1), 6, if(ISBLANK('2025'!$T13), 0, 1), 7, 0))), 1, "") -> 1 | K13: =IF(AND(AND(AND(K$4>='2025'!$L13,K$4<='2025'!$M13), K$4<>DATE(2025,7,4)), (SWITCH(weekday(K$4), 1, 0, 2, if(ISBLANK('2025'!$P13), 0, 1), 3, if(ISBLANK('2025'!$Q13), 0, 1), 4, if(ISBLANK('2025'!$R13), 0, 1), 5, if(ISBLANK('2025'!$S13), 0, 1), 6, if(ISBLANK('2025'!$T13), 0, 1), 7, 0))), 1, "") -> 1 | ... BF13: =IF(AND(AND(AND(BF$4>='2025'!$L13,BF$4<='2025'!$M13), BF$4<>DATE(2025,7,4)), (SWITCH(weekday(BF$4), 1, 0, 2, if(ISBLANK('2025'!$P13), 0, 1), 3, if(ISBLANK('2025'!$Q13), 0, 1), 4, if(ISBLANK('2025'!$R13), 0, 1), 5, if(ISBLANK('2025'!$S13), 0, 1), 6, if(ISBLANK('2025'!$T13), 0, 1), 7, 0))), 1, "") -> 1
A14: =A13+1 -> 14 | B14: ='2025'!D14 -> Cesta, Nancy | C14: ='2025'!H14 -> PK3.1 | D14: =IF(AND(AND(AND(D$4>='2025'!$L14,D$4<='2025'!$M14), D$4<>DATE(2025,7,4)), (SWITCH(weekday(D$4), 1, 0, 2, if(ISBLANK('2025'!$P14), 0, 1), 3, if(ISBLANK('2025'!$Q14), 0, 1), 4, if(ISBLANK('2025'!$R14), 0, 1), 5, if(ISBLANK('2025'!$S14), 0, 1), 6, if(ISBLANK('2025'!$T14), 0, 1), 7, 0))), 1, "") | E14: =IF(AND(AND(AND(E$4>='2025'!$L14,E$4<='2025'!$M14), E$4<>DATE(2025,7,4)), (SWITCH(weekday(E$4), 1, 0, 2, if(ISBLANK('2025'!$P14), 0, 1), 3, if(ISBLANK('2025'!$Q14), 0, 1), 4, if(ISBLANK('2025'!$R14), 0, 1), 5, if(ISBLANK('2025'!$S14), 0, 1), 6, if(ISBLANK('2025'!$T14), 0, 1), 7, 0))), 1, "") | F14: =IF(AND(AND(AND(F$4>='2025'!$L14,F$4<='2025'!$M14), F$4<>DATE(2025,7,4)), (SWITCH(weekday(F$4), 1, 0, 2, if(ISBLANK('2025'!$P14), 0, 1), 3, if(ISBLANK('2025'!$Q14), 0, 1), 4, if(ISBLANK('2025'!$R14), 0, 1), 5, if(ISBLANK('2025'!$S14), 0, 1), 6, if(ISBLANK('2025'!$T14), 0, 1), 7, 0))), 1, "") | G14: =IF(AND(AND(AND(G$4>='2025'!$L14,G$4<='2025'!$M14), G$4<>DATE(2025,7,4)), (SWITCH(weekday(G$4), 1, 0, 2, if(ISBLANK('2025'!$P14), 0, 1), 3, if(ISBLANK('2025'!$Q14), 0, 1), 4, if(ISBLANK('2025'!$R14), 0, 1), 5, if(ISBLANK('2025'!$S14), 0, 1), 6, if(ISBLANK('2025'!$T14), 0, 1), 7, 0))), 1, "") | H14: =IF(AND(AND(AND(H$4>='2025'!$L14,H$4<='2025'!$M14), H$4<>DATE(2025,7,4)), (SWITCH(weekday(H$4), 1, 0, 2, if(ISBLANK('2025'!$P14), 0, 1), 3, if(ISBLANK('2025'!$Q14), 0, 1), 4, if(ISBLANK('2025'!$R14), 0, 1), 5, if(ISBLANK('2025'!$S14), 0, 1), 6, if(ISBLANK('2025'!$T14), 0, 1), 7, 0))), 1, "") | I14: =IF(AND(AND(AND(I$4>='2025'!$L14,I$4<='2025'!$M14), I$4<>DATE(2025,7,4)), (SWITCH(weekday(I$4), 1, 0, 2, if(ISBLANK('2025'!$P14), 0, 1), 3, if(ISBLANK('2025'!$Q14), 0, 1), 4, if(ISBLANK('2025'!$R14), 0, 1), 5, if(ISBLANK('2025'!$S14), 0, 1), 6, if(ISBLANK('2025'!$T14), 0, 1), 7, 0))), 1, "") | J14: =IF(AND(AND(AND(J$4>='2025'!$L14,J$4<='2025'!$M14), J$4<>DATE(2025,7,4)), (SWITCH(weekday(J$4), 1, 0, 2, if(ISBLANK('2025'!$P14), 0, 1), 3, if(ISBLANK('2025'!$Q14), 0, 1), 4, if(ISBLANK('2025'!$R14), 0, 1), 5, if(ISBLANK('2025'!$S14), 0, 1), 6, if(ISBLANK('2025'!$T14), 0, 1), 7, 0))), 1, "") | K14: =IF(AND(AND(AND(K$4>='2025'!$L14,K$4<='2025'!$M14), K$4<>DATE(2025,7,4)), (SWITCH(weekday(K$4), 1, 0, 2, if(ISBLANK('2025'!$P14), 0, 1), 3, if(ISBLANK('2025'!$Q14), 0, 1), 4, if(ISBLANK('2025'!$R14), 0, 1), 5, if(ISBLANK('2025'!$S14), 0, 1), 6, if(ISBLANK('2025'!$T14), 0, 1), 7, 0))), 1, "") | ... BF14: =IF(AND(AND(AND(BF$4>='2025'!$L14,BF$4<='2025'!$M14), BF$4<>DATE(2025,7,4)), (SWITCH(weekday(BF$4), 1, 0, 2, if(ISBLANK('2025'!$P14), 0, 1), 3, if(ISBLANK('2025'!$Q14), 0, 1), 4, if(ISBLANK('2025'!$R14), 0, 1), 5, if(ISBLANK('2025'!$S14), 0, 1), 6, if(ISBLANK('2025'!$T14), 0, 1), 7, 0))), 1, "")
A15: =A14+1 -> 15 | B15: ='2025'!D15 -> Abraham, Rebecca | C15: ='2025'!H15 -> PK4 | D15: =IF(AND(AND(AND(D$4>='2025'!$L15,D$4<='2025'!$M15), D$4<>DATE(2025,7,4)), (SWITCH(weekday(D$4), 1, 0, 2, if(ISBLANK('2025'!$P15), 0, 1), 3, if(ISBLANK('2025'!$Q15), 0, 1), 4, if(ISBLANK('2025'!$R15), 0, 1), 5, if(ISBLANK('2025'!$S15), 0, 1), 6, if(ISBLANK('2025'!$T15), 0, 1), 7, 0))), 1, "") | E15: =IF(AND(AND(AND(E$4>='2025'!$L15,E$4<='2025'!$M15), E$4<>DATE(2025,7,4)), (SWITCH(weekday(E$4), 1, 0, 2, if(ISBLANK('2025'!$P15), 0, 1), 3, if(ISBLANK('2025'!$Q15), 0, 1), 4, if(ISBLANK('2025'!$R15), 0, 1), 5, if(ISBLANK('2025'!$S15), 0, 1), 6, if(ISBLANK('2025'!$T15), 0, 1), 7, 0))), 1, "") | F15: =IF(AND(AND(AND(F$4>='2025'!$L15,F$4<='2025'!$M15), F$4<>DATE(2025,7,4)), (SWITCH(weekday(F$4), 1, 0, 2, if(ISBLANK('2025'!$P15), 0, 1), 3, if(ISBLANK('2025'!$Q15), 0, 1), 4, if(ISBLANK('2025'!$R15), 0, 1), 5, if(ISBLANK('2025'!$S15), 0, 1), 6, if(ISBLANK('2025'!$T15), 0, 1), 7, 0))), 1, "") | G15: =IF(AND(AND(AND(G$4>='2025'!$L15,G$4<='2025'!$M15), G$4<>DATE(2025,7,4)), (SWITCH(weekday(G$4), 1, 0, 2, if(ISBLANK('2025'!$P15), 0, 1), 3, if(ISBLANK('2025'!$Q15), 0, 1), 4, if(ISBLANK('2025'!$R15), 0, 1), 5, if(ISBLANK('2025'!$S15), 0, 1), 6, if(ISBLANK('2025'!$T15), 0, 1), 7, 0))), 1, "") | H15: =IF(AND(AND(AND(H$4>='2025'!$L15,H$4<='2025'!$M15), H$4<>DATE(2025,7,4)), (SWITCH(weekday(H$4), 1, 0, 2, if(ISBLANK('2025'!$P15), 0, 1), 3, if(ISBLANK('2025'!$Q15), 0, 1), 4, if(ISBLANK('2025'!$R15), 0, 1), 5, if(ISBLANK('2025'!$S15), 0, 1), 6, if(ISBLANK('2025'!$T15), 0, 1), 7, 0))), 1, "") | I15: =IF(AND(AND(AND(I$4>='2025'!$L15,I$4<='2025'!$M15), I$4<>DATE(2025,7,4)), (SWITCH(weekday(I$4), 1, 0, 2, if(ISBLANK('2025'!$P15), 0, 1), 3, if(ISBLANK('2025'!$Q15), 0, 1), 4, if(ISBLANK('2025'!$R15), 0, 1), 5, if(ISBLANK('2025'!$S15), 0, 1), 6, if(ISBLANK('2025'!$T15), 0, 1), 7, 0))), 1, "") | J15: =IF(AND(AND(AND(J$4>='2025'!$L15,J$4<='2025'!$M15), J$4<>DATE(2025,7,4)), (SWITCH(weekday(J$4), 1, 0, 2, if(ISBLANK('2025'!$P15), 0, 1), 3, if(ISBLANK('2025'!$Q15), 0, 1), 4, if(ISBLANK('2025'!$R15), 0, 1), 5, if(ISBLANK('2025'!$S15), 0, 1), 6, if(ISBLANK('2025'!$T15), 0, 1), 7, 0))), 1, "") | K15: =IF(AND(AND(AND(K$4>='2025'!$L15,K$4<='2025'!$M15), K$4<>DATE(2025,7,4)), (SWITCH(weekday(K$4), 1, 0, 2, if(ISBLANK('2025'!$P15), 0, 1), 3, if(ISBLANK('2025'!$Q15), 0, 1), 4, if(ISBLANK('2025'!$R15), 0, 1), 5, if(ISBLANK('2025'!$S15), 0, 1), 6, if(ISBLANK('2025'!$T15), 0, 1), 7, 0))), 1, "") | ... BF15: =IF(AND(AND(AND(BF$4>='2025'!$L15,BF$4<='2025'!$M15), BF$4<>DATE(2025,7,4)), (SWITCH(weekday(BF$4), 1, 0, 2, if(ISBLANK('2025'!$P15), 0, 1), 3, if(ISBLANK('2025'!$Q15), 0, 1), 4, if(ISBLANK('2025'!$R15), 0, 1), 5, if(ISBLANK('2025'!$S15), 0, 1), 6, if(ISBLANK('2025'!$T15), 0, 1), 7, 0))), 1, "")
A16: =A15+1 -> 16 | B16: ='2025'!D16 -> Kerney, Greyson | C16: ='2025'!H16 -> PK3.1 | D16: =IF(AND(AND(AND(D$4>='2025'!$L16,D$4<='2025'!$M16), D$4<>DATE(2025,7,4)), (SWITCH(weekday(D$4), 1, 0, 2, if(ISBLANK('2025'!$P16), 0, 1), 3, if(ISBLANK('2025'!$Q16), 0, 1), 4, if(ISBLANK('2025'!$R16), 0, 1), 5, if(ISBLANK('2025'!$S16), 0, 1), 6, if(ISBLANK('2025'!$T16), 0, 1), 7, 0))), 1, "") | E16: =IF(AND(AND(AND(E$4>='2025'!$L16,E$4<='2025'!$M16), E$4<>DATE(2025,7,4)), (SWITCH(weekday(E$4), 1, 0, 2, if(ISBLANK('2025'!$P16), 0, 1), 3, if(ISBLANK('2025'!$Q16), 0, 1), 4, if(ISBLANK('2025'!$R16), 0, 1), 5, if(ISBLANK('2025'!$S16), 0, 1), 6, if(ISBLANK('2025'!$T16), 0, 1), 7, 0))), 1, "") | F16: =IF(AND(AND(AND(F$4>='2025'!$L16,F$4<='2025'!$M16), F$4<>DATE(2025,7,4)), (SWITCH(weekday(F$4), 1, 0, 2, if(ISBLANK('2025'!$P16), 0, 1), 3, if(ISBLANK('2025'!$Q16), 0, 1), 4, if(ISBLANK('2025'!$R16), 0, 1), 5, if(ISBLANK('2025'!$S16), 0, 1), 6, if(ISBLANK('2025'!$T16), 0, 1), 7, 0))), 1, "") | G16: =IF(AND(AND(AND(G$4>='2025'!$L16,G$4<='2025'!$M16), G$4<>DATE(2025,7,4)), (SWITCH(weekday(G$4), 1, 0, 2, if(ISBLANK('2025'!$P16), 0, 1), 3, if(ISBLANK('2025'!$Q16), 0, 1), 4, if(ISBLANK('2025'!$R16), 0, 1), 5, if(ISBLANK('2025'!$S16), 0, 1), 6, if(ISBLANK('2025'!$T16), 0, 1), 7, 0))), 1, "") | H16: =IF(AND(AND(AND(H$4>='2025'!$L16,H$4<='2025'!$M16), H$4<>DATE(2025,7,4)), (SWITCH(weekday(H$4), 1, 0, 2, if(ISBLANK('2025'!$P16), 0, 1), 3, if(ISBLANK('2025'!$Q16), 0, 1), 4, if(ISBLANK('2025'!$R16), 0, 1), 5, if(ISBLANK('2025'!$S16), 0, 1), 6, if(ISBLANK('2025'!$T16), 0, 1), 7, 0))), 1, "") | I16: =IF(AND(AND(AND(I$4>='2025'!$L16,I$4<='2025'!$M16), I$4<>DATE(2025,7,4)), (SWITCH(weekday(I$4), 1, 0, 2, if(ISBLANK('2025'!$P16), 0, 1), 3, if(ISBLANK('2025'!$Q16), 0, 1), 4, if(ISBLANK('2025'!$R16), 0, 1), 5, if(ISBLANK('2025'!$S16), 0, 1), 6, if(ISBLANK('2025'!$T16), 0, 1), 7, 0))), 1, "") | J16: =IF(AND(AND(AND(J$4>='2025'!$L16,J$4<='2025'!$M16), J$4<>DATE(2025,7,4)), (SWITCH(weekday(J$4), 1, 0, 2, if(ISBLANK('2025'!$P16), 0, 1), 3, if(ISBLANK('2025'!$Q16), 0, 1), 4, if(ISBLANK('2025'!$R16), 0, 1), 5, if(ISBLANK('2025'!$S16), 0, 1), 6, if(ISBLANK('2025'!$T16), 0, 1), 7, 0))), 1, "") | K16: =IF(AND(AND(AND(K$4>='2025'!$L16,K$4<='2025'!$M16), K$4<>DATE(2025,7,4)), (SWITCH(weekday(K$4), 1, 0, 2, if(ISBLANK('2025'!$P16), 0, 1), 3, if(ISBLANK('2025'!$Q16), 0, 1), 4, if(ISBLANK('2025'!$R16), 0, 1), 5, if(ISBLANK('2025'!$S16), 0, 1), 6, if(ISBLANK('2025'!$T16), 0, 1), 7, 0))), 1, "") | ... BF16: =IF(AND(AND(AND(BF$4>='2025'!$L16,BF$4<='2025'!$M16), BF$4<>DATE(2025,7,4)), (SWITCH(weekday(BF$4), 1, 0, 2, if(ISBLANK('2025'!$P16), 0, 1), 3, if(ISBLANK('2025'!$Q16), 0, 1), 4, if(ISBLANK('2025'!$R16), 0, 1), 5, if(ISBLANK('2025'!$S16), 0, 1), 6, if(ISBLANK('2025'!$T16), 0, 1), 7, 0))), 1, "")
